Workbook

Sheet Model_all_famine
A1: code | B1: country | C1: Group | D1: GDP per cap | E1: Correl | F1: Urban Population Rate (%) | G1: est_1 | H1: est_2 | I1: est_3 | J1: est_4 | K1: famine
A2: 228 | B2: United Arab Emirates | C2: 1 | D2: 84127.607 | E2: 0 | F2: 78.386933 | G2: =IF(E2=1,IF(D2>$N$6,0,IF(F2>=$N$7,0,1)),0) -> 0 | H2: =IF(D2>$R$6,0,IF(F2>=$R$7,0,1)) -> 0 | I2: =IF(E2=1,IF(D2<$V$6,1,0),0) -> 0 | J2: =IF(E2=1,IF(F2<$Z$7,1,0),0) -> 0 | K2: 0 | M2: GDP, Correl, Urban | O2: Model | Q2: GDP, Urban | S2: Model | U2: GDP, Correl | W2: Model | Y2: Correl, Urban | AA2: Model
A3: 210 | B3: Switzerland | C3: 1 | D3: 30299.48 | E3: 0 | F3: 59.261 | G3: =IF(E3=1,IF(D3>$N$6,0,IF(F3>=$N$7,0,1)),0) -> 0 | H3: =IF(D3>$R$6,0,IF(F3>=$R$7,0,1)) -> 0 | I3: =IF(E3=1,IF(D3<$V$6,1,0),0) -> 0 | J3: =IF(E3=1,IF(F3<$Z$7,1,0),0) -> 0 | K3: 0 | O3: o | P3: x | S3: o | T3: x | W3: o | X3: x | AA3: o | AB3: x
A4: 164 | B4: Norway | C4: 1 | D4: 29664.01 | E4: 0 | F4: 66.0246 | G4: =IF(E4=1,IF(D4>$N$6,0,IF(F4>=$N$7,0,1)),0) -> 0 | H4: =IF(D4>$R$6,0,IF(F4>=$R$7,0,1)) -> 0 | I4: =IF(E4=1,IF(D4<$V$6,1,0),0) -> 0 | J4: =IF(E4=1,IF(F4<$Z$7,1,0),0) -> 0 | K4: 0 | M4: Actual | N4: o | O4: =COUNTIFS(G2:G124,"=1",K2:K124,"=1") -> 12 | P4: =COUNTIFS(G2:G124,"=0",K2:K124,"=1") -> 7 | Q4: Actual | R4: o | S4: =COUNTIFS(H2:H124,"=1",K2:K124,"=1") -> 17 | T4: =COUNTIFS(H2:H124,"=0",K2:K124,"=1") -> 2 | U4: Actual | V4: o | W4: =COUNTIFS(I2:I124,"=1",K2:K124,"=1") -> 12 | X4: =COUNTIFS(I2:I124,"=0",K2:K124,"=1") -> 7 | Y4: Actual | Z4: o | AA4: =COUNTIFS(J2:J124,"=1",K2:K124,"=1") -> 12 | AB4: =COUNTIFS(J2:J124,"=0",K2:K124,"=1") -> 7
A5: 118 | B5: Kuwait | C5: 1 | D5: 26520.202 | E5: 0 | F5: 89.2906 | G5: =IF(E5=1,IF(D5>$N$6,0,IF(F5>=$N$7,0,1)),0) -> 0 | H5: =IF(D5>$R$6,0,IF(F5>=$R$7,0,1)) -> 0 | I5: =IF(E5=1,IF(D5<$V$6,1,0),0) -> 0 | J5: =IF(E5=1,IF(F5<$Z$7,1,0),0) -> 0 | K5: 0 | N5: x | O5: =COUNTIFS(G2:G124,"=1",K2:K124,"=0") -> 6 | P5: =COUNTIFS(G2:G124,"=0",K2:K124,"=0") -> 98 | R5: x | S5: =COUNTIFS(H2:H124,"=1",K2:K124,"=0") -> 24 | T5: =COUNTIFS(H2:H124,"=0",K2:K124,"=0") -> 80 | V5: x | W5: =COUNTIFS(I2:I124,"=1",K2:K124,"=0") -> 18 | X5: =COUNTIFS(I2:I124,"=0",K2:K124,"=0") -> 86 | Z5: x | AA5: =COUNTIFS(J2:J124,"=1",K2:K124,"=0") -> 6 | AB5: =COUNTIFS(J2:J124,"=0",K2:K124,"=0") -> 98
A6: 58 | B6: Czech Republic | C6: 1 | D6: 25000 | E6: 0 | F6: 69.303033 | G6: =IF(E6=1,IF(D6>$N$6,0,IF(F6>=$N$7,0,1)),0) -> 0 | H6: =IF(D6>$R$6,0,IF(F6>=$R$7,0,1)) -> 0 | I6: =IF(E6=1,IF(D6<$V$6,1,0),0) -> 0 | J6: =IF(E6=1,IF(F6<$Z$7,1,0),0) -> 0 | K6: 0 | M6: GDP | N6: 10000 | O6: Sum | P6: =SUM(O4:P5) -> 123 | Q6: GDP | R6: 10000 | S6: Sum | T6: =SUM(S4:T5) -> 123 | U6: GDP | V6: 10000 | W6: Sum | X6: =SUM(W4:X5) -> 123 | Y6: GDP | Z6: 10000 | AA6: Sum | AB6: =SUM(AA4:AB5) -> 123
A7: 15 | B7: Austria | C7: 1 | D7: 22919.097 | E7: 0 | F7: 65.319 | G7: =IF(E7=1,IF(D7>$N$6,0,IF(F7>=$N$7,0,1)),0) -> 0 | H7: =IF(D7>$R$6,0,IF(F7>=$R$7,0,1)) -> 0 | I7: =IF(E7=1,IF(D7<$V$6,1,0),0) -> 0 | J7: =IF(E7=1,IF(F7<$Z$7,1,0),0) -> 0 | K7: 0 | M7: Urban Population | N7: 25 | O7: Sum_est | P7: =SUM(G2:G124) -> 18 | Q7: Urban Population | R7: 25 | S7: Sum_est | T7: =SUM(H2:H124) -> 41 | U7: Urban Population | V7: 25 | W7: Sum_est | X7: =SUM(I2:I124) -> 30 | Y7: Urban Population | Z7: 25 | AA7: Sum_est | AB7: =SUM(J2:J124) -> 18
A8: 81 | B8: Germany | C8: 1 | D8: 22853.347 | E8: 0 | F8: 72.4614 | G8: =IF(E8=1,IF(D8>$N$6,0,IF(F8>=$N$7,0,1)),0) -> 0 | H8: =IF(D8>$R$6,0,IF(F8>=$R$7,0,1)) -> 0 | I8: =IF(E8=1,IF(D8<$V$6,1,0),0) -> 0 | J8: =IF(E8=1,IF(F8<$Z$7,1,0),0) -> 0 | K8: 0 | M8: HIT | N8: =(O4+P5)/SUM(O4:P5)*100 -> 89.430894 | O8: Sum_fam | P8: =SUM(K2:K124) -> 19 | Q8: HIT | R8: =(S4+T5)/SUM(S4:T5)*100 -> 78.861789 | S8: Sum_fam | T8: =SUM(K2:K124) -> 19 | U8: HIT | V8: =(W4+X5)/SUM(W4:X5)*100 -> 79.674797 | W8: Sum_fam | X8: =SUM(K2:K124) -> 19 | Y8: HIT | Z8: =(AA4+AB5)/SUM(AA4:AB5)*100 -> 89.430894 | AA8: Sum_fam | AB8: =SUM(K2:K124) -> 19
A9: 209 | B9: Sweden | C9: 1 | D9: 22502.773 | E9: 0 | F9: 80.977167 | G9: =IF(E9=1,IF(D9>$N$6,0,IF(F9>=$N$7,0,1)),0) -> 0 | H9: =IF(D9>$R$6,0,IF(F9>=$R$7,0,1)) -> 0 | I9: =IF(E9=1,IF(D9<$V$6,1,0),0) -> 0 | J9: =IF(E9=1,IF(F9<$Z$7,1,0),0) -> 0 | K9: 0 | AA9: G3にfamineがないから
A10: 191 | B10: Saudi Arabia | C10: 1 | D10: 22209.259 | E10: 0 | F10: 57.123967 | G10: =IF(E10=1,IF(D10>$N$6,0,IF(F10>=$N$7,0,1)),0) -> 0 | H10: =IF(D10>$R$6,0,IF(F10>=$R$7,0,1)) -> 0 | I10: =IF(E10=1,IF(D10<$V$6,1,0),0) -> 0 | J10: =IF(E10=1,IF(F10<$Z$7,1,0),0) -> 0 | K10: 0
A11: 74 | B11: France | C11: 1 | D11: 21928.43 | E11: 0 | F11: 71.194933 | G11: =IF(E11=1,IF(D11>$N$6,0,IF(F11>=$N$7,0,1)),0) -> 0 | H11: =IF(D11>$R$6,0,IF(F11>=$R$7,0,1)) -> 0 | I11: =IF(E11=1,IF(D11<$V$6,1,0),0) -> 0 | J11: =IF(E11=1,IF(F11<$Z$7,1,0),0) -> 0 | K11: 0
A12: 110 | B12: Japan | C12: 1 | D12: 21875.4 | E12: 0 | F12: 73.343033 | G12: =IF(E12=1,IF(D12>$N$6,0,IF(F12>=$N$7,0,1)),0) -> 0 | H12: =IF(D12>$R$6,0,IF(F12>=$R$7,0,1)) -> 0 | I12: =IF(E12=1,IF(D12<$V$6,1,0),0) -> 0 | J12: =IF(E12=1,IF(F12<$Z$7,1,0),0) -> 0 | K12: 0
A13: 73 | B13: Finland | C13: 1 | D13: 20449.505 | E13: 0 | F13: 68.077367 | G13: =IF(E13=1,IF(D13>$N$6,0,IF(F13>=$N$7,0,1)),0) -> 0 | H13: =IF(D13>$R$6,0,IF(F13>=$R$7,0,1)) -> 0 | I13: =IF(E13=1,IF(D13<$V$6,1,0),0) -> 0 | J13: =IF(E13=1,IF(F13<$Z$7,1,0),0) -> 0 | K13: 0
A14: 157 | B14: New Zealand | C14: 1 | D14: 18754.859 | E14: 0 | F14: 81.852733 | G14: =IF(E14=1,IF(D14>$N$6,0,IF(F14>=$N$7,0,1)),0) -> 0 | H14: =IF(D14>$R$6,0,IF(F14>=$R$7,0,1)) -> 0 | I14: =IF(E14=1,IF(D14<$V$6,1,0),0) -> 0 | J14: =IF(E14=1,IF(F14<$Z$7,1,0),0) -> 0 | K14: 0
A15: 203 | B15: Spain | C15: 1 | D15: 16883.632 | E15: 0 | F15: 68.6209 | G15: =IF(E15=1,IF(D15>$N$6,0,IF(F15>=$N$7,0,1)),0) -> 0 | H15: =IF(D15>$R$6,0,IF(F15>=$R$7,0,1)) -> 0 | I15: =IF(E15=1,IF(D15<$V$6,1,0),0) -> 0 | J15: =IF(E15=1,IF(F15<$Z$7,1,0),0) -> 0 | K15: 0
A16: 84 | B16: Greece | C16: 1 | D16: 16659.472 | E16: 0 | F16: 53.9962 | G16: =IF(E16=1,IF(D16>$N$6,0,IF(F16>=$N$7,0,1)),0) -> 0 | H16: =IF(D16>$R$6,0,IF(F16>=$R$7,0,1)) -> 0 | I16: =IF(E16=1,IF(D16<$V$6,1,0),0) -> 0 | J16: =IF(E16=1,IF(F16<$Z$7,1,0),0) -> 0 | K16: 0
A17: 107 | B17: Israel | C17: 1 | D17: 16454.964 | E17: 0 | F17: 85.857267 | G17: =IF(E17=1,IF(D17>$N$6,0,IF(F17>=$N$7,0,1)),0) -> 0 | H17: =IF(D17>$R$6,0,IF(F17>=$R$7,0,1)) -> 0 | I17: =IF(E17=1,IF(D17<$V$6,1,0),0) -> 0 | J17: =IF(E17=1,IF(F17<$Z$7,1,0),0) -> 0 | K17: 0
A18: 78 | B18: Gabon | C18: 1 | D18: 15656.96 | E18: 0 | F18: 44.045833 | G18: =IF(E18=1,IF(D18>$N$6,0,IF(F18>=$N$7,0,1)),0) -> 0 | H18: =IF(D18>$R$6,0,IF(F18>=$R$7,0,1)) -> 0 | I18: =IF(E18=1,IF(D18<$V$6,1,0),0) -> 0 | J18: =IF(E18=1,IF(F18<$Z$7,1,0),0) -> 0 | K18: 0
A19: 105 | B19: Ireland | C19: 1 | D19: 14370.902 | E19: 0 | F19: 53.024233 | G19: =IF(E19=1,IF(D19>$N$6,0,IF(F19>=$N$7,0,1)),0) -> 0 | H19: =IF(D19>$R$6,0,IF(F19>=$R$7,0,1)) -> 0 | I19: =IF(E19=1,IF(D19<$V$6,1,0),0) -> 0 | J19: =IF(E19=1,IF(F19<$Z$7,1,0),0) -> 0 | K19: 0
A20: 176 | B20: Portugal | C20: 1 | D20: 13353.044 | E20: 0 | F20: 41.2105 | G20: =IF(E20=1,IF(D20>$N$6,0,IF(F20>=$N$7,0,1)),0) -> 0 | H20: =IF(D20>$R$6,0,IF(F20>=$R$7,0,1)) -> 0 | I20: =IF(E20=1,IF(D20<$V$6,1,0),0) -> 0 | J20: =IF(E20=1,IF(F20<$Z$7,1,0),0) -> 0 | K20: 0
A21: 125 | B21: Libyan Arab Jamahiriya | C21: 1 | D21: 13000 | E21: 0 | F21: 58.004833 | G21: =IF(E21=1,IF(D21>$N$6,0,IF(F21>=$N$7,0,1)),0) -> 0 | H21: =IF(D21>$R$6,0,IF(F21>=$R$7,0,1)) -> 0 | I21: =IF(E21=1,IF(D21<$V$6,1,0),0) -> 0 | J21: =IF(E21=1,IF(F21<$Z$7,1,0),0) -> 0 | K21: 0
... A124: 243 | B124: Zimbabwe | C124: 4 | D124: 400 | E124: 1 | F124: 20.346 | G124: =IF(E124=1,IF(D124>$N$6,0,IF(F124>=$N$7,0,1)),0) -> 1 | H124: =IF(D124>$R$6,0,IF(F124>=$R$7,0,1)) -> 1 | I124: =IF(E124=1,IF(D124<$V$6,1,0),0) -> 1 | J124: =IF(E124=1,IF(F124<$Z$7,1,0),0) -> 1 | K124: 1
A125: 12 | B125: Armenia | E125: 1 | F125: 62.199933
A126: 16 | B126: Azerbaijan | E126: 1 | F126: 52.109767
A127: 18 | B127: Bahrain | E127: 1 | F127: 85.053
A128: 21 | B128: Belarus | E128: 1 | F128: 50.605167
A129: 28 | B129: Bosnia And Herzegovina | E129: 1 | F129: 30.9339
A130: 51 | B130: Congo, The Democratic Republic Of The | E130: 1 | F130: 28.0273 | K130: 1
A131: 54 | B131: Cote D'Ivoire | E131: 1 | F131: 31.718267
A132: 55 | B132: Croatia | E132: 1 | F132: 44.522667
A133: 57 | B133: Cyprus | E133: 1 | F133: 50.639133
A134: 67 | B134: Eritrea | E134: 1 | F134: 13.4004 | K134: 1
A135: 68 | B135: Estonia | E135: 1 | F135: 66.675333
A136: 80 | B136: Georgia | E136: 1 | F136: 50.137567
A137: 98 | B137: Hong Kong | E137: 1
A138: 113 | B138: Kazakhstan | E138: 1 | F138: 51.9063
A139: 119 | B139: Kyrgyzstan | E139: 1 | F139: 37.474267
A140: 120 | B140: Lao People'S Democratic Republic | E140: 1 | F140: 11.2751
A141: 121 | B141: Latvia | E141: 1 | F141: 63.3423
A142: 127 | B142: Lithuania | E142: 1 | F142: 55.369967
...

Sheet Model_drought_induced_famine
A1: code | B1: country | C1: Group | D1: GDP per cap | E1: Correl | F1: Urban Population Rate (%) | G1: est_1 | H1: est_2 | I1: est_3 | J1: est_4 | K1: famine | M1: est_1 | Q1: est_2 | U1: est_3 | Y1: est_4
A2: 228 | B2: United Arab Emirates | C2: 1 | D2: 84127.607 | E2: 0 | F2: 78.386933 | G2: =IF(E2=1,IF(D2>$N$6,0,IF(F2>=$N$7,0,1)),0) -> 0 | H2: =IF(D2>$R$6,0,IF(F2>=$R$7,0,1)) -> 0 | I2: =IF(E2=1,IF(D2<$V$6,1,0),0) -> 0 | J2: =IF(E2=1,IF(F2<$Z$7,1,0),0) -> 0 | K2: 0 | M2: GDP, Correl, Urban | O2: Model | Q2: GDP, Urban | S2: Model | U2: GDP, Correl | W2: Model | Y2: Correl, Urban | AA2: Model
A3: 210 | B3: Switzerland | C3: 1 | D3: 30299.48 | E3: 0 | F3: 59.261 | G3: =IF(E3=1,IF(D3>$N$6,0,IF(F3>=$N$7,0,1)),0) -> 0 | H3: =IF(D3>$R$6,0,IF(F3>=$R$7,0,1)) -> 0 | I3: =IF(E3=1,IF(D3<$V$6,1,0),0) -> 0 | J3: =IF(E3=1,IF(F3<$Z$7,1,0),0) -> 0 | K3: 0 | O3: o | P3: x | S3: o | T3: x | W3: o | X3: x | AA3: o | AB3: x
A4: 164 | B4: Norway | C4: 1 | D4: 29664.01 | E4: 0 | F4: 66.0246 | G4: =IF(E4=1,IF(D4>$N$6,0,IF(F4>=$N$7,0,1)),0) -> 0 | H4: =IF(D4>$R$6,0,IF(F4>=$R$7,0,1)) -> 0 | I4: =IF(E4=1,IF(D4<$V$6,1,0),0) -> 0 | J4: =IF(E4=1,IF(F4<$Z$7,1,0),0) -> 0 | K4: 0 | M4: Actual | N4: o | O4: =COUNTIFS(G2:G124,"=1",K2:K124,"=1") -> 12 | P4: =COUNTIFS(G2:G124,"=0",K2:K124,"=1") -> 3 | Q4: Actual | R4: o | S4: =COUNTIFS(H2:H124,"=1",K2:K124,"=1") -> 15 | T4: =COUNTIFS(H2:H124,"=0",K2:K124,"=1") -> 0 | U4: Actual | V4: o | W4: =COUNTIFS(I2:I124,"=1",K2:K124,"=1") -> 12 | X4: =COUNTIFS(I2:I124,"=0",K2:K124,"=1") -> 3 | Y4: Actual | Z4: o | AA4: =COUNTIFS(J2:J124,"=1",K2:K124,"=1") -> 12 | AB4: =COUNTIFS(J2:J124,"=0",K2:K124,"=1") -> 3
A5: 118 | B5: Kuwait | C5: 1 | D5: 26520.202 | E5: 0 | F5: 89.2906 | G5: =IF(E5=1,IF(D5>$N$6,0,IF(F5>=$N$7,0,1)),0) -> 0 | H5: =IF(D5>$R$6,0,IF(F5>=$R$7,0,1)) -> 0 | I5: =IF(E5=1,IF(D5<$V$6,1,0),0) -> 0 | J5: =IF(E5=1,IF(F5<$Z$7,1,0),0) -> 0 | K5: 0 | N5: x | O5: =COUNTIFS(G2:G124,"=1",K2:K124,"=0") -> 5 | P5: =COUNTIFS(G2:G124,"=0",K2:K124,"=0") -> 102 | R5: x | S5: =COUNTIFS(H2:H124,"=1",K2:K124,"=0") -> 26 | T5: =COUNTIFS(H2:H124,"=0",K2:K124,"=0") -> 82 | V5: x | W5: =COUNTIFS(I2:I124,"=1",K2:K124,"=0") -> 18 | X5: =COUNTIFS(I2:I124,"=0",K2:K124,"=0") -> 90 | Z5: x | AA5: =COUNTIFS(J2:J124,"=1",K2:K124,"=0") -> 6 | AB5: =COUNTIFS(J2:J124,"=0",K2:K124,"=0") -> 102
A6: 58 | B6: Czech Republic | C6: 1 | D6: 25000 | E6: 0 | F6: 69.303033 | G6: =IF(E6=1,IF(D6>$N$6,0,IF(F6>=$N$7,0,1)),0) -> 0 | H6: =IF(D6>$R$6,0,IF(F6>=$R$7,0,1)) -> 0 | I6: =IF(E6=1,IF(D6<$V$6,1,0),0) -> 0 | J6: =IF(E6=1,IF(F6<$Z$7,1,0),0) -> 0 | K6: 0 | M6: GDP | N6: 10000 | O6: Sum | P6: =SUM(O4:P5) -> 122 | Q6: GDP | R6: 10000 | S6: Sum | T6: =SUM(S4:T5) -> 123 | U6: GDP | V6: 10000 | W6: Sum | X6: =SUM(W4:X5) -> 123 | Y6: GDP | Z6: 10000 | AA6: Sum | AB6: =SUM(AA4:AB5) -> 123
A7: 15 | B7: Austria | C7: 1 | D7: 22919.097 | E7: 0 | F7: 65.319 | G7: =IF(E7=1,IF(D7>$N$6,0,IF(F7>=$N$7,0,1)),0) -> 0 | H7: =IF(D7>$R$6,0,IF(F7>=$R$7,0,1)) -> 0 | I7: =IF(E7=1,IF(D7<$V$6,1,0),0) -> 0 | J7: =IF(E7=1,IF(F7<$Z$7,1,0),0) -> 0 | K7: 0 | M7: Urban Population | N7: 25 | O7: Sum_est | P7: =SUM(G2:G124) -> 17 | Q7: Urban Population | R7: 25 | S7: Sum_est | T7: =SUM(H2:H124) -> 41 | U7: Urban Population | V7: 25 | W7: Sum_est | X7: =SUM(I2:I124) -> 30 | Y7: Urban Population | Z7: 25 | AA7: Sum_est | AB7: =SUM(N2:N124) -> 10118.443
A8: 81 | B8: Germany | C8: 1 | D8: 22853.347 | E8: 0 | F8: 72.4614 | G8: =IF(E8=1,IF(D8>$N$6,0,IF(F8>=$N$7,0,1)),0) -> 0 | H8: =IF(D8>$R$6,0,IF(F8>=$R$7,0,1)) -> 0 | I8: =IF(E8=1,IF(D8<$V$6,1,0),0) -> 0 | J8: =IF(E8=1,IF(F8<$Z$7,1,0),0) -> 0 | K8: 0 | M8: HIT | N8: =(O4+P5)/SUM(O4:P5)*100 -> 93.442623 | O8: Sum_fam | P8: =SUM(K2:K124) -> 15 | Q8: HIT | R8: =(S4+T5)/SUM(S4:T5)*100 -> 78.861789 | S8: Sum_fam | T8: =SUM(K2:K124) -> 15 | U8: HIT | V8: =(W4+X5)/SUM(W4:X5)*100 -> 82.926829 | W8: Sum_fam | X8: =SUM(K2:K124) -> 15 | Y8: HIT | Z8: =(AA4+AB5)/SUM(AA4:AB5)*100 -> 92.682927 | AA8: Sum_fam | AB8: =SUM(O2:O124) -> 17
A9: 209 | B9: Sweden | C9: 1 | D9: 22502.773 | E9: 0 | F9: 80.977167 | G9: =IF(E9=1,IF(D9>$N$6,0,IF(F9>=$N$7,0,1)),0) -> 0 | H9: =IF(D9>$R$6,0,IF(F9>=$R$7,0,1)) -> 0 | I9: =IF(E9=1,IF(D9<$V$6,1,0),0) -> 0 | J9: =IF(E9=1,IF(F9<$Z$7,1,0),0) -> 0 | K9: 0
A10: 191 | B10: Saudi Arabia | C10: 1 | D10: 22209.259 | E10: 0 | F10: 57.123967 | G10: =IF(E10=1,IF(D10>$N$6,0,IF(F10>=$N$7,0,1)),0) -> 0 | H10: =IF(D10>$R$6,0,IF(F10>=$R$7,0,1)) -> 0 | I10: =IF(E10=1,IF(D10<$V$6,1,0),0) -> 0 | J10: =IF(E10=1,IF(F10<$Z$7,1,0),0) -> 0 | K10: 0
A11: 74 | B11: France | C11: 1 | D11: 21928.43 | E11: 0 | F11: 71.194933 | G11: =IF(E11=1,IF(D11>$N$6,0,IF(F11>=$N$7,0,1)),0) -> 0 | H11: =IF(D11>$R$6,0,IF(F11>=$R$7,0,1)) -> 0 | I11: =IF(E11=1,IF(D11<$V$6,1,0),0) -> 0 | J11: =IF(E11=1,IF(F11<$Z$7,1,0),0) -> 0 | K11: 0
A12: 110 | B12: Japan | C12: 1 | D12: 21875.4 | E12: 0 | F12: 73.343033 | G12: =IF(E12=1,IF(D12>$N$6,0,IF(F12>=$N$7,0,1)),0) -> 0 | H12: =IF(D12>$R$6,0,IF(F12>=$R$7,0,1)) -> 0 | I12: =IF(E12=1,IF(D12<$V$6,1,0),0) -> 0 | J12: =IF(E12=1,IF(F12<$Z$7,1,0),0) -> 0 | K12: 0
A13: 73 | B13: Finland | C13: 1 | D13: 20449.505 | E13: 0 | F13: 68.077367 | G13: =IF(E13=1,IF(D13>$N$6,0,IF(F13>=$N$7,0,1)),0) -> 0 | H13: =IF(D13>$R$6,0,IF(F13>=$R$7,0,1)) -> 0 | I13: =IF(E13=1,IF(D13<$V$6,1,0),0) -> 0 | J13: =IF(E13=1,IF(F13<$Z$7,1,0),0) -> 0 | K13: 0
A14: 157 | B14: New Zealand | C14: 1 | D14: 18754.859 | E14: 0 | F14: 81.852733 | G14: =IF(E14=1,IF(D14>$N$6,0,IF(F14>=$N$7,0,1)),0) -> 0 | H14: =IF(D14>$R$6,0,IF(F14>=$R$7,0,1)) -> 0 | I14: =IF(E14=1,IF(D14<$V$6,1,0),0) -> 0 | J14: =IF(E14=1,IF(F14<$Z$7,1,0),0) -> 0 | K14: 0
A15: 203 | B15: Spain | C15: 1 | D15: 16883.632 | E15: 0 | F15: 68.6209 | G15: =IF(E15=1,IF(D15>$N$6,0,IF(F15>=$N$7,0,1)),0) -> 0 | H15: =IF(D15>$R$6,0,IF(F15>=$R$7,0,1)) -> 0 | I15: =IF(E15=1,IF(D15<$V$6,1,0),0) -> 0 | J15: =IF(E15=1,IF(F15<$Z$7,1,0),0) -> 0 | K15: 0
A16: 84 | B16: Greece | C16: 1 | D16: 16659.472 | E16: 0 | F16: 53.9962 | G16: =IF(E16=1,IF(D16>$N$6,0,IF(F16>=$N$7,0,1)),0) -> 0 | H16: =IF(D16>$R$6,0,IF(F16>=$R$7,0,1)) -> 0 | I16: =IF(E16=1,IF(D16<$V$6,1,0),0) -> 0 | J16: =IF(E16=1,IF(F16<$Z$7,1,0),0) -> 0 | K16: 0
A17: 107 | B17: Israel | C17: 1 | D17: 16454.964 | E17: 0 | F17: 85.857267 | G17: =IF(E17=1,IF(D17>$N$6,0,IF(F17>=$N$7,0,1)),0) -> 0 | H17: =IF(D17>$R$6,0,IF(F17>=$R$7,0,1)) -> 0 | I17: =IF(E17=1,IF(D17<$V$6,1,0),0) -> 0 | J17: =IF(E17=1,IF(F17<$Z$7,1,0),0) -> 0 | K17: 0
A18: 78 | B18: Gabon | C18: 1 | D18: 15656.96 | E18: 0 | F18: 44.045833 | G18: =IF(E18=1,IF(D18>$N$6,0,IF(F18>=$N$7,0,1)),0) -> 0 | H18: =IF(D18>$R$6,0,IF(F18>=$R$7,0,1)) -> 0 | I18: =IF(E18=1,IF(D18<$V$6,1,0),0) -> 0 | J18: =IF(E18=1,IF(F18<$Z$7,1,0),0) -> 0 | K18: 0
A19: 105 | B19: Ireland | C19: 1 | D19: 14370.902 | E19: 0 | F19: 53.024233 | G19: =IF(E19=1,IF(D19>$N$6,0,IF(F19>=$N$7,0,1)),0) -> 0 | H19: =IF(D19>$R$6,0,IF(F19>=$R$7,0,1)) -> 0 | I19: =IF(E19=1,IF(D19<$V$6,1,0),0) -> 0 | J19: =IF(E19=1,IF(F19<$Z$7,1,0),0) -> 0 | K19: 0
A20: 176 | B20: Portugal | C20: 1 | D20: 13353.044 | E20: 0 | F20: 41.2105 | G20: =IF(E20=1,IF(D20>$N$6,0,IF(F20>=$N$7,0,1)),0) -> 0 | H20: =IF(D20>$R$6,0,IF(F20>=$R$7,0,1)) -> 0 | I20: =IF(E20=1,IF(D20<$V$6,1,0),0) -> 0 | J20: =IF(E20=1,IF(F20<$Z$7,1,0),0) -> 0 | K20: 0
... A104: 146 | B104: Mongolia | C104: 4 | D104: 2328.6067 | E104: 1 | F104: 48.572733 | G104: =IF(E104=1,IF(D104>$N$6,0,IF(F104>=$N$7,0,1)),0) -> 0 | H104: =IF(D104>$R$6,0,IF(F104>=$R$7,0,1)) -> 0 | I104: =IF(E104=1,IF(D104<$V$6,1,0),0) -> 1 | J104: =IF(E104=1,IF(F104<$Z$7,1,0),0) -> 0 | K104: 0
A105: 102 | B105: Indonesia | C105: 4 | D105: 1627.7631 | E105: 1 | F105: 20.759133 | G105: d | H105: =IF(D105>$R$6,0,IF(F105>=$R$7,0,1)) -> 1 | I105: =IF(E105=1,IF(D105<$V$6,1,0),0) -> 1 | J105: =IF(E105=1,IF(F105<$Z$7,1,0),0) -> 1 | K105: 0
A106: 139 | B106: Mauritania | C106: 4 | D106: 1615.7271 | E106: 1 | F106: 22.3571 | G106: =IF(E106=1,IF(D106>$N$6,0,IF(F106>=$N$7,0,1)),0) -> 1 | H106: =IF(D106>$R$6,0,IF(F106>=$R$7,0,1)) -> 1 | I106: =IF(E106=1,IF(D106<$V$6,1,0),0) -> 1 | J106: =IF(E106=1,IF(F106<$Z$7,1,0),0) -> 1 | K106: 1
A107: 192 | B107: Senegal | C107: 4 | D107: 1541.2844 | E107: 1 | F107: 32.650333 | G107: =IF(E107=1,IF(D107>$N$6,0,IF(F107>=$N$7,0,1)),0) -> 0 | H107: =IF(D107>$R$6,0,IF(F107>=$R$7,0,1)) -> 0 | I107: =IF(E107=1,IF(D107<$V$6,1,0),0) -> 1 | J107: =IF(E107=1,IF(F107<$Z$7,1,0),0) -> 0 | K107: 0
A108: 242 | B108: Zambia | C108: 4 | D108: 1363.586 | E108: 1 | F108: 33.171533 | G108: =IF(E108=1,IF(D108>$N$6,0,IF(F108>=$N$7,0,1)),0) -> 0 | H108: =IF(D108>$R$6,0,IF(F108>=$R$7,0,1)) -> 0 | I108: =IF(E108=1,IF(D108<$V$6,1,0),0) -> 1 | J108: =IF(E108=1,IF(F108<$Z$7,1,0),0) -> 0 | K108: 0
A109: 114 | B109: Kenya | C109: 4 | D109: 1351.5256 | E109: 1 | F109: 12.744933 | G109: =IF(E109=1,IF(D109>$N$6,0,IF(F109>=$N$7,0,1)),0) -> 1 | H109: =IF(D109>$R$6,0,IF(F109>=$R$7,0,1)) -> 1 | I109: =IF(E109=1,IF(D109<$V$6,1,0),0) -> 1 | J109: =IF(E109=1,IF(F109<$Z$7,1,0),0) -> 1 | K109: 1
A110: 24 | B110: Benin | C110: 4 | D110: 1177.9327 | E110: 1 | F110: 22.275 | G110: =IF(E110=1,IF(D110>$N$6,0,IF(F110>=$N$7,0,1)),0) -> 1 | H110: =IF(D110>$R$6,0,IF(F110>=$R$7,0,1)) -> 1 | I110: =IF(E110=1,IF(D110<$V$6,1,0),0) -> 1 | J110: =IF(E110=1,IF(F110<$Z$7,1,0),0) -> 1 | K110: 0
A111: 101 | B111: India | C111: 4 | D111: 1063.5797 | E111: 1 | F111: 21.6368 | G111: =IF(E111=1,IF(D111>$N$6,0,IF(F111>=$N$7,0,1)),0) -> 1 | H111: =IF(D111>$R$6,0,IF(F111>=$R$7,0,1)) -> 1 | I111: =IF(E111=1,IF(D111<$V$6,1,0),0) -> 1 | J111: =IF(E111=1,IF(F111<$Z$7,1,0),0) -> 1 | K111: 1
A112: 205 | B112: Sudan | C112: 4 | D112: 1054.9745 | E112: 1 | F112: 18.866567 | G112: =IF(E112=1,IF(D112>$N$6,0,IF(F112>=$N$7,0,1)),0) -> 1 | H112: =IF(D112>$R$6,0,IF(F112>=$R$7,0,1)) -> 1 | I112: =IF(E112=1,IF(D112<$V$6,1,0),0) -> 1 | J112: =IF(E112=1,IF(F112<$Z$7,1,0),0) -> 1 | K112: 1
A113: 217 | B113: Togo | C113: 4 | D113: 943.69276 | E113: 1 | F113: 21.9291 | G113: =IF(E113=1,IF(D113>$N$6,0,IF(F113>=$N$7,0,1)),0) -> 1 | H113: =IF(D113>$R$6,0,IF(F113>=$R$7,0,1)) -> 1 | I113: =IF(E113=1,IF(D113<$V$6,1,0),0) -> 1 | J113: =IF(E113=1,IF(F113<$Z$7,1,0),0) -> 1 | K113: 0
A114: 82 | B114: Ghana | C114: 4 | D114: 856.62119 | E114: 1 | F114: 30.0554 | G114: =IF(E114=1,IF(D114>$N$6,0,IF(F114>=$N$7,0,1)),0) -> 0 | H114: =IF(D114>$R$6,0,IF(F114>=$R$7,0,1)) -> 0 | I114: =IF(E114=1,IF(D114<$V$6,1,0),0) -> 1 | J114: =IF(E114=1,IF(F114<$Z$7,1,0),0) -> 0 | K114: 0
A115: 91 | B115: Guinea | C115: 4 | D115: 849.10381 | E115: 1 | F115: 19.952067 | G115: =IF(E115=1,IF(D115>$N$6,0,IF(F115>=$N$7,0,1)),0) -> 1 | H115: =IF(D115>$R$6,0,IF(F115>=$R$7,0,1)) -> 1 | I115: =IF(E115=1,IF(D115<$V$6,1,0),0) -> 1 | J115: =IF(E115=1,IF(F115<$Z$7,1,0),0) -> 1 | K115: 0
A116: 43 | B116: Chad | C116: 4 | D116: 783.97599 | E116: 1 | F116: 14.878433 | G116: =IF(E116=1,IF(D116>$N$6,0,IF(F116>=$N$7,0,1)),0) -> 1 | H116: =IF(D116>$R$6,0,IF(F116>=$R$7,0,1)) -> 1 | I116: =IF(E116=1,IF(D116<$V$6,1,0),0) -> 1 | J116: =IF(E116=1,IF(F116<$Z$7,1,0),0) -> 1 | K116: 1
A117: 159 | B117: Niger | C117: 4 | D117: 771.11229 | E117: 1 | F117: 11.089833 | G117: =IF(E117=1,IF(D117>$N$6,0,IF(F117>=$N$7,0,1)),0) -> 1 | H117: =IF(D117>$R$6,0,IF(F117>=$R$7,0,1)) -> 1 | I117: =IF(E117=1,IF(D117<$V$6,1,0),0) -> 1 | J117: =IF(E117=1,IF(F117<$Z$7,1,0),0) -> 1 | K117: 1
... A124: 243 | B124: Zimbabwe | C124: 4 | D124: 400 | E124: 1 | F124: 20.346 | G124: =IF(E124=1,IF(D124>$N$6,0,IF(F124>=$N$7,0,1)),0) -> 1 | H124: =IF(D124>$R$6,0,IF(F124>=$R$7,0,1)) -> 1 | I124: =IF(E124=1,IF(D124<$V$6,1,0),0) -> 1 | J124: =IF(E124=1,IF(F124<$Z$7,1,0),0) -> 1 | K124: 1
A125: 12 | B125: Armenia | E125: 1 | F125: 62.199933
A126: 16 | B126: Azerbaijan | E126: 1 | F126: 52.109767
A127: 18 | B127: Bahrain | E127: 1 | F127: 85.053
A128: 21 | B128: Belarus | E128: 1 | F128: 50.605167
A129: 28 | B129: Bosnia And Herzegovina | E129: 1 | F129: 30.9339
...

Sheet Model_drought_induced_famine_ch
A1: code | B1: country | C1: Group | D1: GDP per cap | E1: Correl | F1: Urban Population Rate (%) | G1: est_former | H1: est_latter | I1: est_3 | J1: est_4 | K1: famine2011 | L1: famine2012 | M1: 1961-1987 | N1: 1988-2012 | O1: est_1 | S1: est_2 | W1: est_3 | AA1: est_4
A2: 228 | B2: United Arab Emirates | C2: 1 | D2: 84127.607 | E2: 0 | F2: 78.386933 | G2: =IF(E2=1,IF(D2>$P$14,0,IF(F2>=$P$15,0,1)),0) -> 0 | H2: =IF(D2>$T$14,0,IF(F2>=$T$15,0,1)) -> 0 | I2: =IF(E2=1,IF(D2<$X$6,1,0),0) -> 0 | J2: =IF(E2=1,IF(F2<$AB$7,1,0),0) -> 0 | K2: 0 | L2: 0 | M2: 0 | N2: 0 | O2: GDP, Correl, Urban | Q2: Model | S2: GDP, Urban | U2: Model | W2: GDP, Correl | Y2: Model | AA2: Correl, Urban | AC2: Model
A3: 210 | B3: Switzerland | C3: 1 | D3: 30299.48 | E3: 0 | F3: 59.261 | G3: =IF(E3=1,IF(D3>$P$14,0,IF(F3>=$P$15,0,1)),0) -> 0 | H3: =IF(D3>$T$14,0,IF(F3>=$T$15,0,1)) -> 0 | I3: =IF(E3=1,IF(D3<$X$6,1,0),0) -> 0 | J3: =IF(E3=1,IF(F3<$AB$7,1,0),0) -> 0 | K3: 0 | L3: 0 | M3: 0 | N3: 0 | Q3: o | R3: x | U3: o | V3: x | Y3: o | Z3: x | AC3: o | AD3: x
A4: 164 | B4: Norway | C4: 1 | D4: 29664.01 | E4: 0 | F4: 66.0246 | G4: =IF(E4=1,IF(D4>$P$14,0,IF(F4>=$P$15,0,1)),0) -> 0 | H4: =IF(D4>$T$14,0,IF(F4>=$T$15,0,1)) -> 0 | I4: =IF(E4=1,IF(D4<$X$6,1,0),0) -> 0 | J4: =IF(E4=1,IF(F4<$AB$7,1,0),0) -> 0 | K4: 0 | L4: 0 | M4: 0 | N4: 0 | O4: Actual | P4: o | Q4: =COUNTIFS(G2:G124,"=1",K2:K124,"=1") -> 12 | R4: =COUNTIFS(G2:G124,"=0",K2:K124,"=1") -> 3 | S4: Actual | T4: o | U4: =COUNTIFS(H2:H124,"=1",K2:K124,"=1") -> 15 | V4: =COUNTIFS(H2:H124,"=0",K2:K124,"=1") -> 0 | W4: Actual | X4: o | Y4: =COUNTIFS(I2:I124,"=1",K2:K124,"=1") -> 12 | Z4: =COUNTIFS(I2:I124,"=0",K2:K124,"=1") -> 3 | AA4: Actual | AB4: o | AC4: =COUNTIFS(J2:J124,"=1",K2:K124,"=1") -> 12 | AD4: =COUNTIFS(J2:J124,"=0",K2:K124,"=1") -> 3
A5: 118 | B5: Kuwait | C5: 1 | D5: 26520.202 | E5: 0 | F5: 89.2906 | G5: =IF(E5=1,IF(D5>$P$14,0,IF(F5>=$P$15,0,1)),0) -> 0 | H5: =IF(D5>$T$14,0,IF(F5>=$T$15,0,1)) -> 0 | I5: =IF(E5=1,IF(D5<$X$6,1,0),0) -> 0 | J5: =IF(E5=1,IF(F5<$AB$7,1,0),0) -> 0 | K5: 0 | L5: 0 | M5: 0 | N5: 0 | P5: x | Q5: =COUNTIFS(G2:G124,"=1",K2:K124,"=0") -> 6 | R5: =COUNTIFS(G2:G124,"=0",K2:K124,"=0") -> 102 | T5: x | U5: =COUNTIFS(H2:H124,"=1",K2:K124,"=0") -> 26 | V5: =COUNTIFS(H2:H124,"=0",K2:K124,"=0") -> 82 | X5: x | Y5: =COUNTIFS(I2:I124,"=1",K2:K124,"=0") -> 18 | Z5: =COUNTIFS(I2:I124,"=0",K2:K124,"=0") -> 90 | AB5: x | AC5: =COUNTIFS(J2:J124,"=1",K2:K124,"=0") -> 6 | AD5: =COUNTIFS(J2:J124,"=0",K2:K124,"=0") -> 102
A6: 58 | B6: Czech Republic | C6: 1 | D6: 25000 | E6: 0 | F6: 69.303033 | G6: =IF(E6=1,IF(D6>$P$14,0,IF(F6>=$P$15,0,1)),0) -> 0 | H6: =IF(D6>$T$14,0,IF(F6>=$T$15,0,1)) -> 0 | I6: =IF(E6=1,IF(D6<$X$6,1,0),0) -> 0 | J6: =IF(E6=1,IF(F6<$AB$7,1,0),0) -> 0 | K6: 0 | L6: 0 | M6: 0 | N6: 0 | O6: GDP | P6: 10000 | Q6: Sum | R6: =SUM(Q4:R5) -> 123 | S6: GDP | T6: 10000 | U6: Sum | V6: =SUM(U4:V5) -> 123 | W6: GDP | X6: 10000 | Y6: Sum | Z6: =SUM(Y4:Z5) -> 123 | AA6: GDP | AB6: 10000 | AC6: Sum | AD6: =SUM(AC4:AD5) -> 123
A7: 15 | B7: Austria | C7: 1 | D7: 22919.097 | E7: 0 | F7: 65.319 | G7: =IF(E7=1,IF(D7>$P$14,0,IF(F7>=$P$15,0,1)),0) -> 0 | H7: =IF(D7>$T$14,0,IF(F7>=$T$15,0,1)) -> 0 | I7: =IF(E7=1,IF(D7<$X$6,1,0),0) -> 0 | J7: =IF(E7=1,IF(F7<$AB$7,1,0),0) -> 0 | K7: 0 | L7: 0 | M7: 0 | N7: 0 | O7: Urban Population | P7: 25 | Q7: Sum_est | R7: =SUM(G2:G124) -> 18 | S7: Urban Population | T7: 25 | U7: Sum_est | V7: =SUM(H2:H124) -> 41 | W7: Urban Population | X7: 25 | Y7: Sum_est | Z7: =SUM(I2:I124) -> 30 | AA7: Urban Population | AB7: 25 | AC7: Sum_est | AD7: =SUM(P2:P124) -> 30350.329
A8: 81 | B8: Germany | C8: 1 | D8: 22853.347 | E8: 0 | F8: 72.4614 | G8: =IF(E8=1,IF(D8>$P$14,0,IF(F8>=$P$15,0,1)),0) -> 0 | H8: =IF(D8>$T$14,0,IF(F8>=$T$15,0,1)) -> 0 | I8: =IF(E8=1,IF(D8<$X$6,1,0),0) -> 0 | J8: =IF(E8=1,IF(F8<$AB$7,1,0),0) -> 0 | K8: 0 | L8: 0 | M8: 0 | N8: 0 | O8: HIT | P8: =(Q4+R5)/SUM(Q4:R5)*100 -> 92.682927 | Q8: Sum_fam | R8: =SUM(K2:K124) -> 15 | S8: HIT | T8: =(U4+V5)/SUM(U4:V5)*100 -> 78.861789 | U8: Sum_fam | V8: =SUM(K2:K124) -> 15 | W8: HIT | X8: =(Y4+Z5)/SUM(Y4:Z5)*100 -> 82.926829 | Y8: Sum_fam | Z8: =SUM(K2:K124) -> 15 | AA8: HIT | AB8: =(AC4+AD5)/SUM(AC4:AD5)*100 -> 92.682927 | AC8: Sum_fam | AD8: =SUM(Q2:Q124) -> 54
A9: 209 | B9: Sweden | C9: 1 | D9: 22502.773 | E9: 0 | F9: 80.977167 | G9: =IF(E9=1,IF(D9>$P$14,0,IF(F9>=$P$15,0,1)),0) -> 0 | H9: =IF(D9>$T$14,0,IF(F9>=$T$15,0,1)) -> 0 | I9: =IF(E9=1,IF(D9<$X$6,1,0),0) -> 0 | J9: =IF(E9=1,IF(F9<$AB$7,1,0),0) -> 0 | K9: 0 | L9: 0 | M9: 0 | N9: 0
A10: 191 | B10: Saudi Arabia | C10: 1 | D10: 22209.259 | E10: 0 | F10: 57.123967 | G10: =IF(E10=1,IF(D10>$P$14,0,IF(F10>=$P$15,0,1)),0) -> 0 | H10: =IF(D10>$T$14,0,IF(F10>=$T$15,0,1)) -> 0 | I10: =IF(E10=1,IF(D10<$X$6,1,0),0) -> 0 | J10: =IF(E10=1,IF(F10<$AB$7,1,0),0) -> 0 | K10: 0 | L10: 0 | M10: 0 | N10: 0 | O10: 1961-1987 | Q10: Model | S10: 1988-2012 | U10: Model | W10: 1961-2012 | Y10: Model
A11: 74 | B11: France | C11: 1 | D11: 21928.43 | E11: 0 | F11: 71.194933 | G11: =IF(E11=1,IF(D11>$P$14,0,IF(F11>=$P$15,0,1)),0) -> 0 | H11: =IF(D11>$T$14,0,IF(F11>=$T$15,0,1)) -> 0 | I11: =IF(E11=1,IF(D11<$X$6,1,0),0) -> 0 | J11: =IF(E11=1,IF(F11<$AB$7,1,0),0) -> 0 | K11: 0 | L11: 0 | M11: 0 | N11: 0 | Q11: o | R11: x | U11: o | V11: x | Y11: o | Z11: x
A12: 110 | B12: Japan | C12: 1 | D12: 21875.4 | E12: 0 | F12: 73.343033 | G12: =IF(E12=1,IF(D12>$P$14,0,IF(F12>=$P$15,0,1)),0) -> 0 | H12: =IF(D12>$T$14,0,IF(F12>=$T$15,0,1)) -> 0 | I12: =IF(E12=1,IF(D12<$X$6,1,0),0) -> 0 | J12: =IF(E12=1,IF(F12<$AB$7,1,0),0) -> 0 | K12: 0 | L12: 0 | M12: 0 | N12: 0 | O12: Actual | P12: o | Q12: =COUNTIFS(G2:G124,"=1",M2:M124,"=1") -> 9 | R12: =COUNTIFS(G2:G124,"=0",M2:M124,"=1") -> 2 | S12: Actual | T12: o | U12: =COUNTIFS(H2:H124,"=1",N2:N124,"=1") -> 12 | V12: =COUNTIFS(H2:H124,"=0",N2:N124,"=1") -> 1 | W12: Actual | X12: o | Y12: =COUNTIFS(I2:I124,"=1",K2:K124,"=1") -> 12 | Z12: =COUNTIFS(I2:I124,"=0",K2:K124,"=1") -> 3
A13: 73 | B13: Finland | C13: 1 | D13: 20449.505 | E13: 0 | F13: 68.077367 | G13: =IF(E13=1,IF(D13>$P$14,0,IF(F13>=$P$15,0,1)),0) -> 0 | H13: =IF(D13>$T$14,0,IF(F13>=$T$15,0,1)) -> 0 | I13: =IF(E13=1,IF(D13<$X$6,1,0),0) -> 0 | J13: =IF(E13=1,IF(F13<$AB$7,1,0),0) -> 0 | K13: 0 | L13: 0 | M13: 0 | N13: 0 | P13: x | Q13: =COUNTIFS(G2:G124,"=1",M2:M124,"=0") -> 9 | R13: =COUNTIFS(G2:G124,"=0",M2:M124,"=0") -> 103 | T13: x | U13: =COUNTIFS(H2:H124,"=1",N2:N124,"=0") -> 29 | V13: =COUNTIFS(H2:H124,"=0",N2:N124,"=0") -> 81 | X13: x | Y13: =COUNTIFS(I2:I124,"=1",K2:K124,"=0") -> 18 | Z13: =COUNTIFS(I2:I124,"=0",K2:K124,"=0") -> 90
A14: 157 | B14: New Zealand | C14: 1 | D14: 18754.859 | E14: 0 | F14: 81.852733 | G14: =IF(E14=1,IF(D14>$P$14,0,IF(F14>=$P$15,0,1)),0) -> 0 | H14: =IF(D14>$T$14,0,IF(F14>=$T$15,0,1)) -> 0 | I14: =IF(E14=1,IF(D14<$X$6,1,0),0) -> 0 | J14: =IF(E14=1,IF(F14<$AB$7,1,0),0) -> 0 | K14: 0 | L14: 0 | M14: 0 | N14: 0 | O14: GDP | P14: 10000 | Q14: Sum | R14: =SUM(Q12:R13) -> 123 | S14: GDP | T14: 10000 | U14: Sum | V14: =SUM(U12:V13) -> 123 | W14: GDP | X14: 10000 | Y14: Sum | Z14: =SUM(Y12:Z13) -> 123
A15: 203 | B15: Spain | C15: 1 | D15: 16883.632 | E15: 0 | F15: 68.6209 | G15: =IF(E15=1,IF(D15>$P$14,0,IF(F15>=$P$15,0,1)),0) -> 0 | H15: =IF(D15>$T$14,0,IF(F15>=$T$15,0,1)) -> 0 | I15: =IF(E15=1,IF(D15<$X$6,1,0),0) -> 0 | J15: =IF(E15=1,IF(F15<$AB$7,1,0),0) -> 0 | K15: 0 | L15: 0 | M15: 0 | N15: 0 | O15: Urban Population | P15: 25 | Q15: Sum_est | R15: =SUM(G10:G132) -> 18 | S15: Urban Population | T15: 25 | U15: Sum_est | V15: =SUM(H10:H132) -> 41 | W15: Urban Population | X15: 25 | Y15: Sum_est | Z15: =SUM(I10:I132) -> 30
A16: 84 | B16: Greece | C16: 1 | D16: 16659.472 | E16: 0 | F16: 53.9962 | G16: =IF(E16=1,IF(D16>$P$14,0,IF(F16>=$P$15,0,1)),0) -> 0 | H16: =IF(D16>$T$14,0,IF(F16>=$T$15,0,1)) -> 0 | I16: =IF(E16=1,IF(D16<$X$6,1,0),0) -> 0 | J16: =IF(E16=1,IF(F16<$AB$7,1,0),0) -> 0 | K16: 0 | L16: 0 | M16: 0 | N16: 0 | O16: HIT | P16: =(Q12+R13)/SUM(Q12:R13)*100 -> 91.056911 | Q16: Sum_fam | R16: =SUM(L2:L124) -> 17 | S16: HIT | T16: =(U12+V13)/SUM(U12:V13)*100 -> 75.609756 | U16: Sum_fam | V16: =SUM(L2:L124) -> 17 | W16: HIT | X16: =(Y12+Z13)/SUM(Y12:Z13)*100 -> 82.926829 | Y16: Sum_fam | Z16: =SUM(L2:L124) -> 17
A17: 107 | B17: Israel | C17: 1 | D17: 16454.964 | E17: 0 | F17: 85.857267 | G17: =IF(E17=1,IF(D17>$P$14,0,IF(F17>=$P$15,0,1)),0) -> 0 | H17: =IF(D17>$T$14,0,IF(F17>=$T$15,0,1)) -> 0 | I17: =IF(E17=1,IF(D17<$X$6,1,0),0) -> 0 | J17: =IF(E17=1,IF(F17<$AB$7,1,0),0) -> 0 | K17: 0 | L17: 0 | M17: 0 | N17: 0
A18: 78 | B18: Gabon | C18: 1 | D18: 15656.96 | E18: 0 | F18: 44.045833 | G18: =IF(E18=1,IF(D18>$P$14,0,IF(F18>=$P$15,0,1)),0) -> 0 | H18: =IF(D18>$T$14,0,IF(F18>=$T$15,0,1)) -> 0 | I18: =IF(E18=1,IF(D18<$X$6,1,0),0) -> 0 | J18: =IF(E18=1,IF(F18<$AB$7,1,0),0) -> 0 | K18: 0 | L18: 0 | M18: 0 | N18: 0 | O18: GDP, Correl, Urban | Q18: Model | S18: GDP, Urban | U18: Model | W18: GDP, Correl | Y18: Model | AA18: Correl, Urban | AC18: Model
A19: 105 | B19: Ireland | C19: 1 | D19: 14370.902 | E19: 0 | F19: 53.024233 | G19: =IF(E19=1,IF(D19>$P$14,0,IF(F19>=$P$15,0,1)),0) -> 0 | H19: =IF(D19>$T$14,0,IF(F19>=$T$15,0,1)) -> 0 | I19: =IF(E19=1,IF(D19<$X$6,1,0),0) -> 0 | J19: =IF(E19=1,IF(F19<$AB$7,1,0),0) -> 0 | K19: 0 | L19: 0 | M19: 0 | N19: 0 | Q19: o | R19: x | U19: o | V19: x | Y19: o | Z19: x | AC19: o | AD19: x
A20: 176 | B20: Portugal | C20: 1 | D20: 13353.044 | E20: 0 | F20: 41.2105 | G20: =IF(E20=1,IF(D20>$P$14,0,IF(F20>=$P$15,0,1)),0) -> 0 | H20: =IF(D20>$T$14,0,IF(F20>=$T$15,0,1)) -> 0 | I20: =IF(E20=1,IF(D20<$X$6,1,0),0) -> 0 | J20: =IF(E20=1,IF(F20<$AB$7,1,0),0) -> 0 | K20: 0 | L20: 0 | M20: 0 | N20: 0 | O20: Actual | P20: o | Q20: =COUNTIFS(G18:G140,"=1",K18:K140,"=1") -> 12 | R20: =COUNTIFS(G18:G140,"=0",K18:K140,"=1") -> 3 | S20: Actual | T20: o | U20: =COUNTIFS(H18:H140,"=1",K18:K140,"=1") -> 15 | V20: =COUNTIFS(H18:H140,"=0",K18:K140,"=1") -> 0 | W20: Actual | X20: o | Y20: =COUNTIFS(I18:I140,"=1",K18:K140,"=1") -> 12 | Z20: =COUNTIFS(I18:I140,"=0",K18:K140,"=1") -> 3 | AA20: Actual | AB20: o | AC20: =COUNTIFS(J18:J140,"=1",K18:K140,"=1") -> 12 | AD20: =COUNTIFS(J18:J140,"=0",K18:K140,"=1") -> 3
A21: 125 | B21: Libyan Arab Jamahiriya | C21: 1 | D21: 13000 | E21: 0 | F21: 58.004833 | G21: =IF(E21=1,IF(D21>$P$14,0,IF(F21>=$P$15,0,1)),0) -> 0 | H21: =IF(D21>$T$14,0,IF(F21>=$T$15,0,1)) -> 0 | I21: =IF(E21=1,IF(D21<$X$6,1,0),0) -> 0 | J21: =IF(E21=1,IF(F21<$AB$7,1,0),0) -> 0 | K21: 0 | L21: 0 | M21: 0 | N21: 0 | P21: x | Q21: =COUNTIFS(G18:G140,"=1",K18:K140,"=0") -> 6 | R21: =COUNTIFS(G18:G140,"=0",K18:K140,"=0") -> 86 | T21: x | U21: =COUNTIFS(H18:H140,"=1",K18:K140,"=0") -> 26 | V21: =COUNTIFS(H18:H140,"=0",K18:K140,"=0") -> 66 | X21: x | Y21: =COUNTIFS(I18:I140,"=1",K18:K140,"=0") -> 18 | Z21: =COUNTIFS(I18:I140,"=0",K18:K140,"=0") -> 74 | AB21: x | AC21: =COUNTIFS(J18:J140,"=1",K18:K140,"=0") -> 6 | AD21: =COUNTIFS(J18:J140,"=0",K18:K140,"=0") -> 86
A22: 220 | B22: Trinidad And Tobago | C22: 1 | D22: 12779.41 | E22: 0 | F22: 11.685833 | G22: =IF(E22=1,IF(D22>$P$14,0,IF(F22>=$P$15,0,1)),0) -> 0 | H22: =IF(D22>$T$14,0,IF(F22>=$T$15,0,1)) -> 0 | I22: =IF(E22=1,IF(D22<$X$6,1,0),0) -> 0 | J22: =IF(E22=1,IF(F22<$AB$7,1,0),0) -> 0 | K22: 0 | L22: 0 | M22: 0 | N22: 0 | O22: GDP | P22: 10000 | Q22: Sum | R22: =SUM(Q20:R21) -> 107 | S22: GDP | T22: 10000 | U22: Sum | V22: =SUM(U20:V21) -> 107 | W22: GDP | X22: 10000 | Y22: Sum | Z22: =SUM(Y20:Z21) -> 107 | AA22: GDP | AB22: 10000 | AC22: Sum | AD22: =SUM(AC20:AD21) -> 107
A23: 142 | B23: Mexico | C23: 1 | D23: 10010.128 | E23: 0 | F23: 62.525433 | G23: =IF(E23=1,IF(D23>$P$14,0,IF(F23>=$P$15,0,1)),0) -> 0 | H23: =IF(D23>$T$14,0,IF(F23>=$T$15,0,1)) -> 0 | I23: =IF(E23=1,IF(D23<$X$6,1,0),0) -> 0 | J23: =IF(E23=1,IF(F23<$AB$7,1,0),0) -> 0 | K23: 0 | L23: 0 | M23: 0 | N23: 0 | O23: Urban Population | P23: 25 | Q23: Sum_est | R23: =SUM(G18:G140) -> 18 | S23: Urban Population | T23: 25 | U23: Sum_est | V23: =SUM(H18:H140) -> 41 | W23: Urban Population | X23: 25 | Y23: Sum_est | Z23: =SUM(I18:I140) -> 30 | AA23: Urban Population | AB23: 25 | AC23: Sum_est | AD23: =SUM(P18:P140) -> 10116.589
A24: 56 | B24: Cuba | C24: 2 | D24: 9900 | E24: 0 | F24: 65.0408 | G24: =IF(E24=1,IF(D24>$P$14,0,IF(F24>=$P$15,0,1)),0) -> 0 | H24: =IF(D24>$T$14,0,IF(F24>=$T$15,0,1)) -> 0 | I24: =IF(E24=1,IF(D24<$X$6,1,0),0) -> 0 | J24: =IF(E24=1,IF(F24<$AB$7,1,0),0) -> 0 | K24: 0 | L24: 0 | M24: 0 | N24: 0 | O24: HIT | P24: =(Q20+R21)/SUM(Q20:R21)*100 -> 91.588785 | Q24: Sum_fam | R24: =SUM(K18:K140) -> 17 | S24: HIT | T24: =(U20+V21)/SUM(U20:V21)*100 -> 75.700935 | U24: Sum_fam | V24: =SUM(K18:K140) -> 17 | W24: HIT | X24: =(Y20+Z21)/SUM(Y20:Z21)*100 -> 80.373832 | Y24: Sum_fam | Z24: =SUM(K18:K140) -> 17 | AA24: HIT | AB24: =(AC20+AD21)/SUM(AC20:AD21)*100 -> 91.588785 | AC24: Sum_fam | AD24: =SUM(Q18:Q140) -> 18
A25: 11 | B25: Argentina | C25: 2 | D25: 8559.8257 | E25: 0 | F25: 80.962967 | G25: =IF(E25=1,IF(D25>$P$14,0,IF(F25>=$P$15,0,1)),0) -> 0 | H25: =IF(D25>$T$14,0,IF(F25>=$T$15,0,1)) -> 0 | I25: =IF(E25=1,IF(D25<$X$6,1,0),0) -> 0 | J25: =IF(E25=1,IF(F25<$AB$7,1,0),0) -> 0 | K25: 0 | L25: 0 | M25: 0 | N25: 0
A26: 180 | B26: Romania | C26: 2 | D26: 8459.8776 | E26: 0 | F26: 43.6953 | G26: =IF(E26=1,IF(D26>$P$14,0,IF(F26>=$P$15,0,1)),0) -> 0 | H26: =IF(D26>$T$14,0,IF(F26>=$T$15,0,1)) -> 0 | I26: =IF(E26=1,IF(D26<$X$6,1,0),0) -> 0 | J26: =IF(E26=1,IF(F26<$AB$7,1,0),0) -> 0 | K26: 0 | L26: 0 | M26: 0 | N26: 0
A27: 201 | B27: South Africa | C27: 2 | D27: 8332.6196 | E27: 0 | F27: 48.472133 | G27: =IF(E27=1,IF(D27>$P$14,0,IF(F27>=$P$15,0,1)),0) -> 0 | H27: =IF(D27>$T$14,0,IF(F27>=$T$15,0,1)) -> 0 | I27: =IF(E27=1,IF(D27<$X$6,1,0),0) -> 0 | J27: =IF(E27=1,IF(F27<$AB$7,1,0),0) -> 0 | K27: 0 | L27: 0 | M27: 0 | N27: 0
A28: 175 | B28: Poland | C28: 2 | D28: 8180.3731 | E28: 0 | F28: 55.2463 | G28: =IF(E28=1,IF(D28>$P$14,0,IF(F28>=$P$15,0,1)),0) -> 0 | H28: =IF(D28>$T$14,0,IF(F28>=$T$15,0,1)) -> 0 | I28: =IF(E28=1,IF(D28<$X$6,1,0),0) -> 0 | J28: =IF(E28=1,IF(F28<$AB$7,1,0),0) -> 0 | K28: 0 | L28: 0 | M28: 0 | N28: 0
A29: 117 | B29: Korea, Republic Of | C29: 2 | D29: 7909.6841 | E29: 0 | F29: 49.679067 | G29: =IF(E29=1,IF(D29>$P$14,0,IF(F29>=$P$15,0,1)),0) -> 0 | H29: =IF(D29>$T$14,0,IF(F29>=$T$15,0,1)) -> 0 | I29: =IF(E29=1,IF(D29<$X$6,1,0),0) -> 0 | J29: =IF(E29=1,IF(F29<$AB$7,1,0),0) -> 0 | K29: 0 | L29: 0 | M29: 0 | N29: 0
A30: 31 | B30: Brazil | C30: 2 | D30: 7199.3902 | E30: 0 | F30: 60.978967 | G30: =IF(E30=1,IF(D30>$P$14,0,IF(F30>=$P$15,0,1)),0) -> 0 | H30: =IF(D30>$T$14,0,IF(F30>=$T$15,0,1)) -> 0 | I30: =IF(E30=1,IF(D30<$X$6,1,0),0) -> 0 | J30: =IF(E30=1,IF(F30<$AB$7,1,0),0) -> 0 | K30: 0 | L30: 0 | M30: 0 | N30: 0
A31: 34 | B31: Bulgaria | C31: 2 | D31: 7087.3317 | E31: 0 | F31: 56.1622 | G31: =IF(E31=1,IF(D31>$P$14,0,IF(F31>=$P$15,0,1)),0) -> 0 | H31: =IF(D31>$T$14,0,IF(F31>=$T$15,0,1)) -> 0 | I31: =IF(E31=1,IF(D31<$X$6,1,0),0) -> 0 | J31: =IF(E31=1,IF(F31<$AB$7,1,0),0) -> 0 | K31: 0 | L31: 0 | M31: 0 | N31: 0
A32: 232 | B32: Uruguay | C32: 2 | D32: 6956.3323 | E32: 0 | F32: 84.191867 | G32: =IF(E32=1,IF(D32>$P$14,0,IF(F32>=$P$15,0,1)),0) -> 0 | H32: =IF(D32>$T$14,0,IF(F32>=$T$15,0,1)) -> 0 | I32: =IF(E32=1,IF(D32<$X$6,1,0),0) -> 0 | J32: =IF(E32=1,IF(F32<$AB$7,1,0),0) -> 0 | K32: 0 | L32: 0 | M32: 0 | N32: 0
A33: 169 | B33: Panama | C33: 2 | D33: 6610.2076 | E33: 0 | F33: 48.7452 | G33: =IF(E33=1,IF(D33>$P$14,0,IF(F33>=$P$15,0,1)),0) -> 0 | H33: =IF(D33>$T$14,0,IF(F33>=$T$15,0,1)) -> 0 | I33: =IF(E33=1,IF(D33<$X$6,1,0),0) -> 0 | J33: =IF(E33=1,IF(F33<$AB$7,1,0),0) -> 0 | K33: 0 | L33: 0 | M33: 0 | N33: 0
A34: 103 | B34: Iran, Islamic Republic Of | C34: 2 | D34: 6601.6239 | E34: 0 | F34: 45.7345 | G34: =IF(E34=1,IF(D34>$P$14,0,IF(F34>=$P$15,0,1)),0) -> 0 | H34: =IF(D34>$T$14,0,IF(F34>=$T$15,0,1)) -> 0 | I34: =IF(E34=1,IF(D34<$X$6,1,0),0) -> 0 | J34: =IF(E34=1,IF(F34<$AB$7,1,0),0) -> 0 | K34: 0 | L34: 0 | M34: 0 | N34: 0
A35: 4 | B35: Algeria | C35: 2 | D35: 6503.1951 | E35: 0 | F35: 42.073 | G35: =IF(E35=1,IF(D35>$P$14,0,IF(F35>=$P$15,0,1)),0) -> 0 | H35: =IF(D35>$T$14,0,IF(F35>=$T$15,0,1)) -> 0 | I35: =IF(E35=1,IF(D35<$X$6,1,0),0) -> 0 | J35: =IF(E35=1,IF(F35<$AB$7,1,0),0) -> 0 | K35: 0 | L35: 0 | M35: 0 | N35: 0
A36: 122 | B36: Lebanon | C36: 2 | D36: 6131.0894 | E36: 0 | F36: 66.2152 | G36: =IF(E36=1,IF(D36>$P$14,0,IF(F36>=$P$15,0,1)),0) -> 0 | H36: =IF(D36>$T$14,0,IF(F36>=$T$15,0,1)) -> 0 | I36: =IF(E36=1,IF(D36<$X$6,1,0),0) -> 0 | J36: =IF(E36=1,IF(F36<$AB$7,1,0),0) -> 0 | K36: 0 | L36: 0 | M36: 0 | N36: 0
... A124: 243 | B124: Zimbabwe | C124: 4 | D124: 400 | E124: 1 | F124: 20.346 | G124: =IF(E124=1,IF(D124>$P$14,0,IF(F124>=$P$15,0,1)),0) -> 1 | H124: =IF(D124>$T$14,0,IF(F124>=$T$15,0,1)) -> 1 | I124: =IF(E124=1,IF(D124<$X$6,1,0),0) -> 1 | J124: =IF(E124=1,IF(F124<$AB$7,1,0),0) -> 1 | K124: 1 | L124: 1 | M124: 0 | N124: 1
A125: 12 | B125: Armenia | E125: 1 | F125: 62.199933 | L125: 0 | M125: 0 | N125: 0
A126: 16 | B126: Azerbaijan | E126: 1 | F126: 52.109767 | L126: 0 | M126: 0 | N126: 0
A127: 18 | B127: Bahrain | E127: 1 | F127: 85.053 | L127: 0 | M127: 0 | N127: 0
...

Sheet 1961-2012_Famine
A1: code | B1: country | C1: 4Groups | D1: 1961 | E1: 1962 | F1: 1963 | G1: 1964 | H1: 1965 | I1: 1966 | J1: 1967 | K1: 1968 | L1: 1969 | M1: 1970 | N1: 1971 | O1: 1972 | P1: 1973 | Q1: 1974 | R1: 1975 | S1: 1976 | T1: 1977 | U1: 1978 | V1: 1979 | W1: 1980 | X1: 1981 | Y1: 1982 | Z1: 1983 | AA1: 1984 | AB1: 1985 | AC1: 1986 | AD1: 1987 | AE1: 1988 | AF1: 1989 | AG1: 1990 | AH1: 1991 | AI1: 1992 | AJ1: 1993 | AK1: 1994 | AL1: 1995 | AM1: 1996 | AN1: 1997 | AO1: 1998 | AP1: 1999 | AQ1: 2000 | AR1: 2001 | AS1: 2002 | AT1: 2003 | AU1: 2004 | AV1: 2005 | AW1: 2006 | AX1: 2007 | AY1: 2008 | AZ1: 2009 | BA1: 2010 | BB1: 2011 | BC1: 2012
A2: 1 | B2: Afghanistan | C2: 2 | BD2: =SUM(D2:AD2) -> 0 | BE2: =SUM(AE2:BC2) -> 0
A3: 3 | B3: Albania | C3: 2 | BD3: =SUM(D3:AD3) -> 0 | BE3: =SUM(AE3:BC3) -> 0
A4: 4 | B4: Algeria | C4: 2 | BD4: =SUM(D4:AD4) -> 0 | BE4: =SUM(AE4:BC4) -> 0
A5: 7 | B5: Angola | C5: 2 | BD5: =SUM(D5:AD5) -> 0 | BE5: =SUM(AE5:BC5) -> 0
A6: 11 | B6: Argentina | C6: 2 | BD6: =SUM(D6:AD6) -> 0 | BE6: =SUM(AE6:BC6) -> 0
A7: 12 | B7: Armenia | BD7: =SUM(D7:AD7) -> 0 | BE7: =SUM(AE7:BC7) -> 0
A8: 14 | B8: Australia | C8: 3 | BD8: =SUM(D8:AD8) -> 0 | BE8: =SUM(AE8:BC8) -> 0
A9: 15 | B9: Austria | C9: 1 | BD9: =SUM(D9:AD9) -> 0 | BE9: =SUM(AE9:BC9) -> 0
A10: 16 | B10: Azerbaijan | BD10: =SUM(D10:AD10) -> 0 | BE10: =SUM(AE10:BC10) -> 0
A11: 18 | B11: Bahrain | BD11: =SUM(D11:AD11) -> 0 | BE11: =SUM(AE11:BC11) -> 0
A12: 19 | B12: Bangladesh | C12: 2 | Q12: 1 | BD12: =SUM(D12:AD12) -> 1 | BE12: =SUM(AE12:BC12) -> 0
A13: 21 | B13: Belarus | BD13: =SUM(D13:AD13) -> 0 | BE13: =SUM(AE13:BC13) -> 0
A14: 22 | B14: Belgium | C14: 3 | BD14: =SUM(D14:AD14) -> 0 | BE14: =SUM(AE14:BC14) -> 0
A15: 24 | B15: Benin | C15: 4 | BD15: =SUM(D15:AD15) -> 0 | BE15: =SUM(AE15:BC15) -> 0
A16: 27 | B16: Bolivia | C16: 2 | BD16: =SUM(D16:AD16) -> 0 | BE16: =SUM(AE16:BC16) -> 0
A17: 28 | B17: Bosnia And Herzegovina | BD17: =SUM(D17:AD17) -> 0 | BE17: =SUM(AE17:BC17) -> 0
A18: 29 | B18: Botswana | C18: 4 | BD18: =SUM(D18:AD18) -> 0 | BE18: =SUM(AE18:BC18) -> 0
A19: 31 | B19: Brazil | C19: 2 | BD19: =SUM(D19:AD19) -> 0 | BE19: =SUM(AE19:BC19) -> 0
A20: 34 | B20: Bulgaria | C20: 2 | BD20: =SUM(D20:AD20) -> 0 | BE20: =SUM(AE20:BC20) -> 0
A21: 35 | B21: Burkina Faso | C21: 4 | K21: 1 | BC21: 1 | BD21: =SUM(D21:AD21) -> 1 | BE21: =SUM(AE21:BC21) -> 1
A22: 36 | B22: Burundi | C22: 2 | BD22: =SUM(D22:AD22) -> 0 | BE22: =SUM(AE22:BC22) -> 0
A23: 37 | B23: Cambodia | C23: 2 | R23: 1 | BD23: =SUM(D23:AD23) -> 1 | BE23: =SUM(AE23:BC23) -> 0
A24: 38 | B24: Cameroon | C24: 2 | BD24: =SUM(D24:AD24) -> 0 | BE24: =SUM(AE24:BC24) -> 0
A25: 39 | B25: Canada | C25: 3 | BD25: =SUM(D25:AD25) -> 0 | BE25: =SUM(AE25:BC25) -> 0
A26: 42 | B26: Central African Republic | C26: 2 | BD26: =SUM(D26:AD26) -> 0 | BE26: =SUM(AE26:BC26) -> 0
A27: 43 | B27: Chad | C27: 4 | K27: 1 | BD27: =SUM(D27:AD27) -> 1 | BE27: =SUM(AE27:BC27) -> 0
A28: 44 | B28: Chile | C28: 2 | BD28: =SUM(D28:AD28) -> 0 | BE28: =SUM(AE28:BC28) -> 0
A29: 45 | B29: China | C29: 2 | BD29: =SUM(D29:AD29) -> 0 | BE29: =SUM(AE29:BC29) -> 0
A30: 48 | B30: Colombia | C30: 2 | BD30: =SUM(D30:AD30) -> 0 | BE30: =SUM(AE30:BC30) -> 0
A31: 50 | B31: Congo | C31: 4 | BD31: =SUM(D31:AD31) -> 0 | BE31: =SUM(AE31:BC31) -> 0
A32: 51 | B32: Congo, The Democratic Republic Of The | AO32: 1 | BD32: =SUM(D32:AD32) -> 0 | BE32: =SUM(AE32:BC32) -> 1
A33: 53 | B33: Costa Rica | C33: 2 | BD33: =SUM(D33:AD33) -> 0 | BE33: =SUM(AE33:BC33) -> 0
A34: 54 | B34: Cote D'Ivoire | BD34: =SUM(D34:AD34) -> 0 | BE34: =SUM(AE34:BC34) -> 0
A35: 55 | B35: Croatia | BD35: =SUM(D35:AD35) -> 0 | BE35: =SUM(AE35:BC35) -> 0
A36: 56 | B36: Cuba | C36: 2 | BD36: =SUM(D36:AD36) -> 0 | BE36: =SUM(AE36:BC36) -> 0
A37: 57 | B37: Cyprus | BD37: =SUM(D37:AD37) -> 0 | BE37: =SUM(AE37:BC37) -> 0
A38: 58 | B38: Czech Republic | C38: 1 | BD38: =SUM(D38:AD38) -> 0 | BE38: =SUM(AE38:BC38) -> 0
A39: 59 | B39: Denmark | C39: 3 | BD39: =SUM(D39:AD39) -> 0 | BE39: =SUM(AE39:BC39) -> 0
A40: 62 | B40: Dominican Republic | C40: 2 | BD40: =SUM(D40:AD40) -> 0 | BE40: =SUM(AE40:BC40) -> 0
...

Sheet all_1961-1990
G1: GDP | H1: 10000 | I1: Urban pop. | J1: 25
A2: code | B2: country | C2: Group | D2: Correl | E2: Urban Population Rate (%) | F2: GDP per cap | G2: 1961 | H2: 1962 | I2: 1963 | J2: 1964 | K2: 1965 | L2: 1966 | M2: 1967 | N2: 1968 | O2: 1969 | P2: 1970 | Q2: 1971 | R2: 1972 | S2: 1973 | T2: 1974 | U2: 1975 | V2: 1976 | W2: 1977 | X2: 1978 | Y2: 1979 | Z2: 1980 | AA2: 1981 | AB2: 1982 | AC2: 1983 | AD2: 1984 | AE2: 1985 | AF2: 1986 | AG2: 1987 | AH2: 1988 | AI2: 1989 | AJ2: 1990 | AK2: 1991 | AL2: 1992 | AM2: 1993 | AN2: 1994 | AO2: 1995 | AP2: 1996 | AQ2: 1997 | AR2: 1998 | AS2: 1999 | AT2: 2000 | AU2: 2001 | AV2: 2002 | AW2: 2003 | AX2: 2004 | AY2: 2005 | AZ2: 2006 | BA2: 2007 | BB2: 2008 | BC2: 2009 | BD2: 2010 | BE2: 2011 | BF2: 2012
A3: 228 | B3: United Arab Emirates | C3: 1 | D3: 0 | E3: 78.386933 | F3: 84127.607 | G3: =IF($D3=1,IF(GDP_per_cap!C147>'all_1961-1990'!$H$1,0,IF(UrbanPopRate!C147>=$J$1,0,1)),0) -> 0 | H3: =IF($D3=1,IF(GDP_per_cap!D147>'all_1961-1990'!$H$1,0,IF(UrbanPopRate!D147>=$J$1,0,1)),0) -> 0 | I3: =IF($D3=1,IF(GDP_per_cap!E147>'all_1961-1990'!$H$1,0,IF(UrbanPopRate!E147>=$J$1,0,1)),0) -> 0 | J3: =IF($D3=1,IF(GDP_per_cap!F147>'all_1961-1990'!$H$1,0,IF(UrbanPopRate!F147>=$J$1,0,1)),0) -> 0 | K3: =IF($D3=1,IF(GDP_per_cap!G147>'all_1961-1990'!$H$1,0,IF(UrbanPopRate!G147>=$J$1,0,1)),0) -> 0 | L3: =IF($D3=1,IF(GDP_per_cap!H147>'all_1961-1990'!$H$1,0,IF(UrbanPopRate!H147>=$J$1,0,1)),0) -> 0 | M3: =IF($D3=1,IF(GDP_per_cap!I147>'all_1961-1990'!$H$1,0,IF(UrbanPopRate!I147>=$J$1,0,1)),0) -> 0 | N3: =IF($D3=1,IF(GDP_per_cap!J147>'all_1961-1990'!$H$1,0,IF(UrbanPopRate!J147>=$J$1,0,1)),0) -> 0 | ... BF3: =IF($D3=1,IF(GDP_per_cap!BB147>'all_1961-1990'!$H$1,0,IF(UrbanPopRate!BB147>=$J$1,0,1)),0) -> 0
A4: 210 | B4: Switzerland | C4: 1 | D4: 0 | E4: 59.261 | F4: 30299.48 | G4: =IF($D4=1,IF(GDP_per_cap!C134>'all_1961-1990'!$H$1,0,IF(UrbanPopRate!C134>=$J$1,0,1)),0) -> 0 | H4: =IF($D4=1,IF(GDP_per_cap!D134>'all_1961-1990'!$H$1,0,IF(UrbanPopRate!D134>=$J$1,0,1)),0) -> 0 | I4: =IF($D4=1,IF(GDP_per_cap!E134>'all_1961-1990'!$H$1,0,IF(UrbanPopRate!E134>=$J$1,0,1)),0) -> 0 | J4: =IF($D4=1,IF(GDP_per_cap!F134>'all_1961-1990'!$H$1,0,IF(UrbanPopRate!F134>=$J$1,0,1)),0) -> 0 | K4: =IF($D4=1,IF(GDP_per_cap!G134>'all_1961-1990'!$H$1,0,IF(UrbanPopRate!G134>=$J$1,0,1)),0) -> 0 | L4: =IF($D4=1,IF(GDP_per_cap!H134>'all_1961-1990'!$H$1,0,IF(UrbanPopRate!H134>=$J$1,0,1)),0) -> 0 | M4: =IF($D4=1,IF(GDP_per_cap!I134>'all_1961-1990'!$H$1,0,IF(UrbanPopRate!I134>=$J$1,0,1)),0) -> 0 | N4: =IF($D4=1,IF(GDP_per_cap!J134>'all_1961-1990'!$H$1,0,IF(UrbanPopRate!J134>=$J$1,0,1)),0) -> 0 | ... BF4: =IF($D4=1,IF(GDP_per_cap!BB134>'all_1961-1990'!$H$1,0,IF(UrbanPopRate!BB134>=$J$1,0,1)),0) -> 0
A5: 164 | B5: Norway | C5: 1 | D5: 0 | E5: 66.0246 | F5: 29664.01 | G5: =IF($D5=1,IF(GDP_per_cap!C105>'all_1961-1990'!$H$1,0,IF(UrbanPopRate!C105>=$J$1,0,1)),0) -> 0 | H5: =IF($D5=1,IF(GDP_per_cap!D105>'all_1961-1990'!$H$1,0,IF(UrbanPopRate!D105>=$J$1,0,1)),0) -> 0 | I5: =IF($D5=1,IF(GDP_per_cap!E105>'all_1961-1990'!$H$1,0,IF(UrbanPopRate!E105>=$J$1,0,1)),0) -> 0 | J5: =IF($D5=1,IF(GDP_per_cap!F105>'all_1961-1990'!$H$1,0,IF(UrbanPopRate!F105>=$J$1,0,1)),0) -> 0 | K5: =IF($D5=1,IF(GDP_per_cap!G105>'all_1961-1990'!$H$1,0,IF(UrbanPopRate!G105>=$J$1,0,1)),0) -> 0 | L5: =IF($D5=1,IF(GDP_per_cap!H105>'all_1961-1990'!$H$1,0,IF(UrbanPopRate!H105>=$J$1,0,1)),0) -> 0 | M5: =IF($D5=1,IF(GDP_per_cap!I105>'all_1961-1990'!$H$1,0,IF(UrbanPopRate!I105>=$J$1,0,1)),0) -> 0 | N5: =IF($D5=1,IF(GDP_per_cap!J105>'all_1961-1990'!$H$1,0,IF(UrbanPopRate!J105>=$J$1,0,1)),0) -> 0 | ... BF5: =IF($D5=1,IF(GDP_per_cap!BB105>'all_1961-1990'!$H$1,0,IF(UrbanPopRate!BB105>=$J$1,0,1)),0) -> 0
A6: 118 | B6: Kuwait | C6: 1 | D6: 0 | E6: 89.2906 | F6: 26520.202 | G6: =IF($D6=1,IF(GDP_per_cap!C76>'all_1961-1990'!$H$1,0,IF(UrbanPopRate!C76>=$J$1,0,1)),0) -> 0 | H6: =IF($D6=1,IF(GDP_per_cap!D76>'all_1961-1990'!$H$1,0,IF(UrbanPopRate!D76>=$J$1,0,1)),0) -> 0 | I6: =IF($D6=1,IF(GDP_per_cap!E76>'all_1961-1990'!$H$1,0,IF(UrbanPopRate!E76>=$J$1,0,1)),0) -> 0 | J6: =IF($D6=1,IF(GDP_per_cap!F76>'all_1961-1990'!$H$1,0,IF(UrbanPopRate!F76>=$J$1,0,1)),0) -> 0 | K6: =IF($D6=1,IF(GDP_per_cap!G76>'all_1961-1990'!$H$1,0,IF(UrbanPopRate!G76>=$J$1,0,1)),0) -> 0 | L6: =IF($D6=1,IF(GDP_per_cap!H76>'all_1961-1990'!$H$1,0,IF(UrbanPopRate!H76>=$J$1,0,1)),0) -> 0 | M6: =IF($D6=1,IF(GDP_per_cap!I76>'all_1961-1990'!$H$1,0,IF(UrbanPopRate!I76>=$J$1,0,1)),0) -> 0 | N6: =IF($D6=1,IF(GDP_per_cap!J76>'all_1961-1990'!$H$1,0,IF(UrbanPopRate!J76>=$J$1,0,1)),0) -> 0 | ... BF6: =IF($D6=1,IF(GDP_per_cap!BB76>'all_1961-1990'!$H$1,0,IF(UrbanPopRate!BB76>=$J$1,0,1)),0) -> 0
A7: 58 | B7: Czech Republic | C7: 1 | D7: 0 | E7: 69.303033 | F7: 25000 | G7: =IF($D7=1,IF(GDP_per_cap!C38>'all_1961-1990'!$H$1,0,IF(UrbanPopRate!C38>=$J$1,0,1)),0) -> 0 | H7: =IF($D7=1,IF(GDP_per_cap!D38>'all_1961-1990'!$H$1,0,IF(UrbanPopRate!D38>=$J$1,0,1)),0) -> 0 | I7: =IF($D7=1,IF(GDP_per_cap!E38>'all_1961-1990'!$H$1,0,IF(UrbanPopRate!E38>=$J$1,0,1)),0) -> 0 | J7: =IF($D7=1,IF(GDP_per_cap!F38>'all_1961-1990'!$H$1,0,IF(UrbanPopRate!F38>=$J$1,0,1)),0) -> 0 | K7: =IF($D7=1,IF(GDP_per_cap!G38>'all_1961-1990'!$H$1,0,IF(UrbanPopRate!G38>=$J$1,0,1)),0) -> 0 | L7: =IF($D7=1,IF(GDP_per_cap!H38>'all_1961-1990'!$H$1,0,IF(UrbanPopRate!H38>=$J$1,0,1)),0) -> 0 | M7: =IF($D7=1,IF(GDP_per_cap!I38>'all_1961-1990'!$H$1,0,IF(UrbanPopRate!I38>=$J$1,0,1)),0) -> 0 | N7: =IF($D7=1,IF(GDP_per_cap!J38>'all_1961-1990'!$H$1,0,IF(UrbanPopRate!J38>=$J$1,0,1)),0) -> 0 | ... BF7: =IF($D7=1,IF(GDP_per_cap!BB38>'all_1961-1990'!$H$1,0,IF(UrbanPopRate!BB38>=$J$1,0,1)),0) -> 0
A8: 15 | B8: Austria | C8: 1 | D8: 0 | E8: 65.319 | F8: 22919.097 | G8: =IF($D8=1,IF(GDP_per_cap!C9>'all_1961-1990'!$H$1,0,IF(UrbanPopRate!C9>=$J$1,0,1)),0) -> 0 | H8: =IF($D8=1,IF(GDP_per_cap!D9>'all_1961-1990'!$H$1,0,IF(UrbanPopRate!D9>=$J$1,0,1)),0) -> 0 | I8: =IF($D8=1,IF(GDP_per_cap!E9>'all_1961-1990'!$H$1,0,IF(UrbanPopRate!E9>=$J$1,0,1)),0) -> 0 | J8: =IF($D8=1,IF(GDP_per_cap!F9>'all_1961-1990'!$H$1,0,IF(UrbanPopRate!F9>=$J$1,0,1)),0) -> 0 | K8: =IF($D8=1,IF(GDP_per_cap!G9>'all_1961-1990'!$H$1,0,IF(UrbanPopRate!G9>=$J$1,0,1)),0) -> 0 | L8: =IF($D8=1,IF(GDP_per_cap!H9>'all_1961-1990'!$H$1,0,IF(UrbanPopRate!H9>=$J$1,0,1)),0) -> 0 | M8: =IF($D8=1,IF(GDP_per_cap!I9>'all_1961-1990'!$H$1,0,IF(UrbanPopRate!I9>=$J$1,0,1)),0) -> 0 | N8: =IF($D8=1,IF(GDP_per_cap!J9>'all_1961-1990'!$H$1,0,IF(UrbanPopRate!J9>=$J$1,0,1)),0) -> 0 | ... BF8: =IF($D8=1,IF(GDP_per_cap!BB9>'all_1961-1990'!$H$1,0,IF(UrbanPopRate!BB9>=$J$1,0,1)),0) -> 0
A9: 81 | B9: Germany | C9: 1 | D9: 0 | E9: 72.4614 | F9: 22853.347 | G9: =IF($D9=1,IF(GDP_per_cap!C52>'all_1961-1990'!$H$1,0,IF(UrbanPopRate!C52>=$J$1,0,1)),0) -> 0 | H9: =IF($D9=1,IF(GDP_per_cap!D52>'all_1961-1990'!$H$1,0,IF(UrbanPopRate!D52>=$J$1,0,1)),0) -> 0 | I9: =IF($D9=1,IF(GDP_per_cap!E52>'all_1961-1990'!$H$1,0,IF(UrbanPopRate!E52>=$J$1,0,1)),0) -> 0 | J9: =IF($D9=1,IF(GDP_per_cap!F52>'all_1961-1990'!$H$1,0,IF(UrbanPopRate!F52>=$J$1,0,1)),0) -> 0 | K9: =IF($D9=1,IF(GDP_per_cap!G52>'all_1961-1990'!$H$1,0,IF(UrbanPopRate!G52>=$J$1,0,1)),0) -> 0 | L9: =IF($D9=1,IF(GDP_per_cap!H52>'all_1961-1990'!$H$1,0,IF(UrbanPopRate!H52>=$J$1,0,1)),0) -> 0 | M9: =IF($D9=1,IF(GDP_per_cap!I52>'all_1961-1990'!$H$1,0,IF(UrbanPopRate!I52>=$J$1,0,1)),0) -> 0 | N9: =IF($D9=1,IF(GDP_per_cap!J52>'all_1961-1990'!$H$1,0,IF(UrbanPopRate!J52>=$J$1,0,1)),0) -> 0 | ... BF9: =IF($D9=1,IF(GDP_per_cap!BB52>'all_1961-1990'!$H$1,0,IF(UrbanPopRate!BB52>=$J$1,0,1)),0) -> 0
A10: 209 | B10: Sweden | C10: 1 | D10: 0 | E10: 80.977167 | F10: 22502.773 | G10: =IF($D10=1,IF(GDP_per_cap!C133>'all_1961-1990'!$H$1,0,IF(UrbanPopRate!C133>=$J$1,0,1)),0) -> 0 | H10: =IF($D10=1,IF(GDP_per_cap!D133>'all_1961-1990'!$H$1,0,IF(UrbanPopRate!D133>=$J$1,0,1)),0) -> 0 | I10: =IF($D10=1,IF(GDP_per_cap!E133>'all_1961-1990'!$H$1,0,IF(UrbanPopRate!E133>=$J$1,0,1)),0) -> 0 | J10: =IF($D10=1,IF(GDP_per_cap!F133>'all_1961-1990'!$H$1,0,IF(UrbanPopRate!F133>=$J$1,0,1)),0) -> 0 | K10: =IF($D10=1,IF(GDP_per_cap!G133>'all_1961-1990'!$H$1,0,IF(UrbanPopRate!G133>=$J$1,0,1)),0) -> 0 | L10: =IF($D10=1,IF(GDP_per_cap!H133>'all_1961-1990'!$H$1,0,IF(UrbanPopRate!H133>=$J$1,0,1)),0) -> 0 | M10: =IF($D10=1,IF(GDP_per_cap!I133>'all_1961-1990'!$H$1,0,IF(UrbanPopRate!I133>=$J$1,0,1)),0) -> 0 | N10: =IF($D10=1,IF(GDP_per_cap!J133>'all_1961-1990'!$H$1,0,IF(UrbanPopRate!J133>=$J$1,0,1)),0) -> 0 | ... BF10: =IF($D10=1,IF(GDP_per_cap!BB133>'all_1961-1990'!$H$1,0,IF(UrbanPopRate!BB133>=$J$1,0,1)),0) -> 0
A11: 191 | B11: Saudi Arabia | C11: 1 | D11: 0 | E11: 57.123967 | F11: 22209.259 | G11: =IF($D11=1,IF(GDP_per_cap!C121>'all_1961-1990'!$H$1,0,IF(UrbanPopRate!C121>=$J$1,0,1)),0) -> 0 | H11: =IF($D11=1,IF(GDP_per_cap!D121>'all_1961-1990'!$H$1,0,IF(UrbanPopRate!D121>=$J$1,0,1)),0) -> 0 | I11: =IF($D11=1,IF(GDP_per_cap!E121>'all_1961-1990'!$H$1,0,IF(UrbanPopRate!E121>=$J$1,0,1)),0) -> 0 | J11: =IF($D11=1,IF(GDP_per_cap!F121>'all_1961-1990'!$H$1,0,IF(UrbanPopRate!F121>=$J$1,0,1)),0) -> 0 | K11: =IF($D11=1,IF(GDP_per_cap!G121>'all_1961-1990'!$H$1,0,IF(UrbanPopRate!G121>=$J$1,0,1)),0) -> 0 | L11: =IF($D11=1,IF(GDP_per_cap!H121>'all_1961-1990'!$H$1,0,IF(UrbanPopRate!H121>=$J$1,0,1)),0) -> 0 | M11: =IF($D11=1,IF(GDP_per_cap!I121>'all_1961-1990'!$H$1,0,IF(UrbanPopRate!I121>=$J$1,0,1)),0) -> 0 | N11: =IF($D11=1,IF(GDP_per_cap!J121>'all_1961-1990'!$H$1,0,IF(UrbanPopRate!J121>=$J$1,0,1)),0) -> 0 | ... BF11: =IF($D11=1,IF(GDP_per_cap!BB121>'all_1961-1990'!$H$1,0,IF(UrbanPopRate!BB121>=$J$1,0,1)),0) -> 0
A12: 74 | B12: France | C12: 1 | D12: 0 | E12: 71.194933 | F12: 21928.43 | G12: =IF($D12=1,IF(GDP_per_cap!C48>'all_1961-1990'!$H$1,0,IF(UrbanPopRate!C48>=$J$1,0,1)),0) -> 0 | H12: =IF($D12=1,IF(GDP_per_cap!D48>'all_1961-1990'!$H$1,0,IF(UrbanPopRate!D48>=$J$1,0,1)),0) -> 0 | I12: =IF($D12=1,IF(GDP_per_cap!E48>'all_1961-1990'!$H$1,0,IF(UrbanPopRate!E48>=$J$1,0,1)),0) -> 0 | J12: =IF($D12=1,IF(GDP_per_cap!F48>'all_1961-1990'!$H$1,0,IF(UrbanPopRate!F48>=$J$1,0,1)),0) -> 0 | K12: =IF($D12=1,IF(GDP_per_cap!G48>'all_1961-1990'!$H$1,0,IF(UrbanPopRate!G48>=$J$1,0,1)),0) -> 0 | L12: =IF($D12=1,IF(GDP_per_cap!H48>'all_1961-1990'!$H$1,0,IF(UrbanPopRate!H48>=$J$1,0,1)),0) -> 0 | M12: =IF($D12=1,IF(GDP_per_cap!I48>'all_1961-1990'!$H$1,0,IF(UrbanPopRate!I48>=$J$1,0,1)),0) -> 0 | N12: =IF($D12=1,IF(GDP_per_cap!J48>'all_1961-1990'!$H$1,0,IF(UrbanPopRate!J48>=$J$1,0,1)),0) -> 0 | ... BF12: =IF($D12=1,IF(GDP_per_cap!BB48>'all_1961-1990'!$H$1,0,IF(UrbanPopRate!BB48>=$J$1,0,1)),0) -> 0
A13: 110 | B13: Japan | C13: 1 | D13: 0 | E13: 73.343033 | F13: 21875.4 | G13: =IF($D13=1,IF(GDP_per_cap!C70>'all_1961-1990'!$H$1,0,IF(UrbanPopRate!C70>=$J$1,0,1)),0) -> 0 | H13: =IF($D13=1,IF(GDP_per_cap!D70>'all_1961-1990'!$H$1,0,IF(UrbanPopRate!D70>=$J$1,0,1)),0) -> 0 | I13: =IF($D13=1,IF(GDP_per_cap!E70>'all_1961-1990'!$H$1,0,IF(UrbanPopRate!E70>=$J$1,0,1)),0) -> 0 | J13: =IF($D13=1,IF(GDP_per_cap!F70>'all_1961-1990'!$H$1,0,IF(UrbanPopRate!F70>=$J$1,0,1)),0) -> 0 | K13: =IF($D13=1,IF(GDP_per_cap!G70>'all_1961-1990'!$H$1,0,IF(UrbanPopRate!G70>=$J$1,0,1)),0) -> 0 | L13: =IF($D13=1,IF(GDP_per_cap!H70>'all_1961-1990'!$H$1,0,IF(UrbanPopRate!H70>=$J$1,0,1)),0) -> 0 | M13: =IF($D13=1,IF(GDP_per_cap!I70>'all_1961-1990'!$H$1,0,IF(UrbanPopRate!I70>=$J$1,0,1)),0) -> 0 | N13: =IF($D13=1,IF(GDP_per_cap!J70>'all_1961-1990'!$H$1,0,IF(UrbanPopRate!J70>=$J$1,0,1)),0) -> 0 | ... BF13: =IF($D13=1,IF(GDP_per_cap!BB70>'all_1961-1990'!$H$1,0,IF(UrbanPopRate!BB70>=$J$1,0,1)),0) -> 0
A14: 73 | B14: Finland | C14: 1 | D14: 0 | E14: 68.077367 | F14: 20449.505 | G14: =IF($D14=1,IF(GDP_per_cap!C47>'all_1961-1990'!$H$1,0,IF(UrbanPopRate!C47>=$J$1,0,1)),0) -> 0 | H14: =IF($D14=1,IF(GDP_per_cap!D47>'all_1961-1990'!$H$1,0,IF(UrbanPopRate!D47>=$J$1,0,1)),0) -> 0 | I14: =IF($D14=1,IF(GDP_per_cap!E47>'all_1961-1990'!$H$1,0,IF(UrbanPopRate!E47>=$J$1,0,1)),0) -> 0 | J14: =IF($D14=1,IF(GDP_per_cap!F47>'all_1961-1990'!$H$1,0,IF(UrbanPopRate!F47>=$J$1,0,1)),0) -> 0 | K14: =IF($D14=1,IF(GDP_per_cap!G47>'all_1961-1990'!$H$1,0,IF(UrbanPopRate!G47>=$J$1,0,1)),0) -> 0 | L14: =IF($D14=1,IF(GDP_per_cap!H47>'all_1961-1990'!$H$1,0,IF(UrbanPopRate!H47>=$J$1,0,1)),0) -> 0 | M14: =IF($D14=1,IF(GDP_per_cap!I47>'all_1961-1990'!$H$1,0,IF(UrbanPopRate!I47>=$J$1,0,1)),0) -> 0 | N14: =IF($D14=1,IF(GDP_per_cap!J47>'all_1961-1990'!$H$1,0,IF(UrbanPopRate!J47>=$J$1,0,1)),0) -> 0 | ... BF14: =IF($D14=1,IF(GDP_per_cap!BB47>'all_1961-1990'!$H$1,0,IF(UrbanPopRate!BB47>=$J$1,0,1)),0) -> 0
A15: 157 | B15: New Zealand | C15: 1 | D15: 0 | E15: 81.852733 | F15: 18754.859 | G15: =IF($D15=1,IF(GDP_per_cap!C101>'all_1961-1990'!$H$1,0,IF(UrbanPopRate!C101>=$J$1,0,1)),0) -> 0 | H15: =IF($D15=1,IF(GDP_per_cap!D101>'all_1961-1990'!$H$1,0,IF(UrbanPopRate!D101>=$J$1,0,1)),0) -> 0 | I15: =IF($D15=1,IF(GDP_per_cap!E101>'all_1961-1990'!$H$1,0,IF(UrbanPopRate!E101>=$J$1,0,1)),0) -> 0 | J15: =IF($D15=1,IF(GDP_per_cap!F101>'all_1961-1990'!$H$1,0,IF(UrbanPopRate!F101>=$J$1,0,1)),0) -> 0 | K15: =IF($D15=1,IF(GDP_per_cap!G101>'all_1961-1990'!$H$1,0,IF(UrbanPopRate!G101>=$J$1,0,1)),0) -> 0 | L15: =IF($D15=1,IF(GDP_per_cap!H101>'all_1961-1990'!$H$1,0,IF(UrbanPopRate!H101>=$J$1,0,1)),0) -> 0 | M15: =IF($D15=1,IF(GDP_per_cap!I101>'all_1961-1990'!$H$1,0,IF(UrbanPopRate!I101>=$J$1,0,1)),0) -> 0 | N15: =IF($D15=1,IF(GDP_per_cap!J101>'all_1961-1990'!$H$1,0,IF(UrbanPopRate!J101>=$J$1,0,1)),0) -> 0 | ... BF15: =IF($D15=1,IF(GDP_per_cap!BB101>'all_1961-1990'!$H$1,0,IF(UrbanPopRate!BB101>=$J$1,0,1)),0) -> 0
A16: 203 | B16: Spain | C16: 1 | D16: 0 | E16: 68.6209 | F16: 16883.632 | G16: =IF($D16=1,IF(GDP_per_cap!C129>'all_1961-1990'!$H$1,0,IF(UrbanPopRate!C129>=$J$1,0,1)),0) -> 0 | H16: =IF($D16=1,IF(GDP_per_cap!D129>'all_1961-1990'!$H$1,0,IF(UrbanPopRate!D129>=$J$1,0,1)),0) -> 0 | I16: =IF($D16=1,IF(GDP_per_cap!E129>'all_1961-1990'!$H$1,0,IF(UrbanPopRate!E129>=$J$1,0,1)),0) -> 0 | J16: =IF($D16=1,IF(GDP_per_cap!F129>'all_1961-1990'!$H$1,0,IF(UrbanPopRate!F129>=$J$1,0,1)),0) -> 0 | K16: =IF($D16=1,IF(GDP_per_cap!G129>'all_1961-1990'!$H$1,0,IF(UrbanPopRate!G129>=$J$1,0,1)),0) -> 0 | L16: =IF($D16=1,IF(GDP_per_cap!H129>'all_1961-1990'!$H$1,0,IF(UrbanPopRate!H129>=$J$1,0,1)),0) -> 0 | M16: =IF($D16=1,IF(GDP_per_cap!I129>'all_1961-1990'!$H$1,0,IF(UrbanPopRate!I129>=$J$1,0,1)),0) -> 0 | N16: =IF($D16=1,IF(GDP_per_cap!J129>'all_1961-1990'!$H$1,0,IF(UrbanPopRate!J129>=$J$1,0,1)),0) -> 0 | ... BF16: =IF($D16=1,IF(GDP_per_cap!BB129>'all_1961-1990'!$H$1,0,IF(UrbanPopRate!BB129>=$J$1,0,1)),0) -> 0
A17: 84 | B17: Greece | C17: 1 | D17: 0 | E17: 53.9962 | F17: 16659.472 | G17: =IF($D17=1,IF(GDP_per_cap!C54>'all_1961-1990'!$H$1,0,IF(UrbanPopRate!C54>=$J$1,0,1)),0) -> 0 | H17: =IF($D17=1,IF(GDP_per_cap!D54>'all_1961-1990'!$H$1,0,IF(UrbanPopRate!D54>=$J$1,0,1)),0) -> 0 | I17: =IF($D17=1,IF(GDP_per_cap!E54>'all_1961-1990'!$H$1,0,IF(UrbanPopRate!E54>=$J$1,0,1)),0) -> 0 | J17: =IF($D17=1,IF(GDP_per_cap!F54>'all_1961-1990'!$H$1,0,IF(UrbanPopRate!F54>=$J$1,0,1)),0) -> 0 | K17: =IF($D17=1,IF(GDP_per_cap!G54>'all_1961-1990'!$H$1,0,IF(UrbanPopRate!G54>=$J$1,0,1)),0) -> 0 | L17: =IF($D17=1,IF(GDP_per_cap!H54>'all_1961-1990'!$H$1,0,IF(UrbanPopRate!H54>=$J$1,0,1)),0) -> 0 | M17: =IF($D17=1,IF(GDP_per_cap!I54>'all_1961-1990'!$H$1,0,IF(UrbanPopRate!I54>=$J$1,0,1)),0) -> 0 | N17: =IF($D17=1,IF(GDP_per_cap!J54>'all_1961-1990'!$H$1,0,IF(UrbanPopRate!J54>=$J$1,0,1)),0) -> 0 | ... BF17: =IF($D17=1,IF(GDP_per_cap!BB54>'all_1961-1990'!$H$1,0,IF(UrbanPopRate!BB54>=$J$1,0,1)),0) -> 0
A18: 107 | B18: Israel | C18: 1 | D18: 0 | E18: 85.857267 | F18: 16454.964 | G18: =IF($D18=1,IF(GDP_per_cap!C67>'all_1961-1990'!$H$1,0,IF(UrbanPopRate!C67>=$J$1,0,1)),0) -> 0 | H18: =IF($D18=1,IF(GDP_per_cap!D67>'all_1961-1990'!$H$1,0,IF(UrbanPopRate!D67>=$J$1,0,1)),0) -> 0 | I18: =IF($D18=1,IF(GDP_per_cap!E67>'all_1961-1990'!$H$1,0,IF(UrbanPopRate!E67>=$J$1,0,1)),0) -> 0 | J18: =IF($D18=1,IF(GDP_per_cap!F67>'all_1961-1990'!$H$1,0,IF(UrbanPopRate!F67>=$J$1,0,1)),0) -> 0 | K18: =IF($D18=1,IF(GDP_per_cap!G67>'all_1961-1990'!$H$1,0,IF(UrbanPopRate!G67>=$J$1,0,1)),0) -> 0 | L18: =IF($D18=1,IF(GDP_per_cap!H67>'all_1961-1990'!$H$1,0,IF(UrbanPopRate!H67>=$J$1,0,1)),0) -> 0 | M18: =IF($D18=1,IF(GDP_per_cap!I67>'all_1961-1990'!$H$1,0,IF(UrbanPopRate!I67>=$J$1,0,1)),0) -> 0 | N18: =IF($D18=1,IF(GDP_per_cap!J67>'all_1961-1990'!$H$1,0,IF(UrbanPopRate!J67>=$J$1,0,1)),0) -> 0 | ... BF18: =IF($D18=1,IF(GDP_per_cap!BB67>'all_1961-1990'!$H$1,0,IF(UrbanPopRate!BB67>=$J$1,0,1)),0) -> 0
A19: 78 | B19: Gabon | C19: 1 | D19: 0 | E19: 44.045833 | F19: 15656.96 | G19: =IF($D19=1,IF(GDP_per_cap!C49>'all_1961-1990'!$H$1,0,IF(UrbanPopRate!C49>=$J$1,0,1)),0) -> 0 | H19: =IF($D19=1,IF(GDP_per_cap!D49>'all_1961-1990'!$H$1,0,IF(UrbanPopRate!D49>=$J$1,0,1)),0) -> 0 | I19: =IF($D19=1,IF(GDP_per_cap!E49>'all_1961-1990'!$H$1,0,IF(UrbanPopRate!E49>=$J$1,0,1)),0) -> 0 | J19: =IF($D19=1,IF(GDP_per_cap!F49>'all_1961-1990'!$H$1,0,IF(UrbanPopRate!F49>=$J$1,0,1)),0) -> 0 | K19: =IF($D19=1,IF(GDP_per_cap!G49>'all_1961-1990'!$H$1,0,IF(UrbanPopRate!G49>=$J$1,0,1)),0) -> 0 | L19: =IF($D19=1,IF(GDP_per_cap!H49>'all_1961-1990'!$H$1,0,IF(UrbanPopRate!H49>=$J$1,0,1)),0) -> 0 | M19: =IF($D19=1,IF(GDP_per_cap!I49>'all_1961-1990'!$H$1,0,IF(UrbanPopRate!I49>=$J$1,0,1)),0) -> 0 | N19: =IF($D19=1,IF(GDP_per_cap!J49>'all_1961-1990'!$H$1,0,IF(UrbanPopRate!J49>=$J$1,0,1)),0) -> 0 | ... BF19: =IF($D19=1,IF(GDP_per_cap!BB49>'all_1961-1990'!$H$1,0,IF(UrbanPopRate!BB49>=$J$1,0,1)),0) -> 0
